Workbook

Sheet Cálculos
B1: Escolha as variáveis ---> | C1: SIM | E1: SIM | G1: NÃO | I1: NÃO | K1: NÃO | M1: NÃO | O1: NÃO | Q1: NÃO | S1: NÃO | U1: NÃO | W1: NÃO | Y1: SIM | AA1: SIM | AC1: SIM | AH1: Construída | AJ1: FAC | AO1: FAT | AT1: FPE | AW1: =C1 -> SIM | AX1: =E1 -> SIM | AY1: =G1 -> NÃO | AZ1: =K1 -> NÃO | BA1: =M1 -> NÃO | BB1: =O1 -> NÃO | BC1: =Q1 -> NÃO | BD1: =S1 -> NÃO | BE1: =U1 -> NÃO | BF1: =W1 -> NÃO | BG1: =Y1 -> SIM | BH1: =AA1 -> SIM | BI1: =AC1 -> SIM
A2: Nº | B2: ENDEREÇO | C2: Localização | E2: Área Construída | G2: Área Territorial | I2: Testada | K2: Prof. Equivalente | M2: Topografia | O2: Relevo | Q2: Superfície | S2: Aproveitamento | U2: Acessibilidade | W2: Id. Apa. Conserva. | Y2: Padrão Const. | AA2: Vaga | AC2: Andar Res | AD2: =IF(AC2="Andar Res",3,2) -> 3 | AE2: Valor | AF2: Valor Unitário | AG2: fon | AH2: Valor Unitário * fon | AJ2: raz | AK2: dif | AL2: x_ac | AM2: n | AO2: raz | AP2: dif | AQ2: x_at | AR2: n | AT2: h1 | AU2: COEF | AW2: fal | AX2: fac | AY2: fat | AZ2: fpe | BA2: ftp | BB2: frv | BC2: fsp | BD2: fap | BE2: fav | BF2: fic | BG2: fpd | BH2: fgv | BI2: fan | BJ2: fator final | BL2: Valor Unitário hom (todos) | BM2: Valor Unitário hom (s/ outliers) | BN2: z-score | BO2: vc | BP2: Status | BT2: Estatíticas iniciais com toda a amostra | BW2: Valores Calculados | CE2: Explicações
A3: 1 | B3: Rua B, 761 | C3: 1 | D3: =C3 -> 1 | E3: 92.09 | K3: =IF(G3="","",G3/I3) | N3: =IF(M$1="SIM",IF(M3="","1",VLOOKUP(M3,Dicionários!$A$2:$B$22,2,0)),"1") -> 1 | P3: =IF(O$1="SIM",IF(O3="","1",VLOOKUP(O3,Dicionários!$C$2:$D$22,2,0)),"1") -> 1 | R3: =IF(Q$1="SIM",IF(Q3="","1",VLOOKUP(Q3,Dicionários!$E$2:$F$22,2,0)),"1") -> 1 | T3: =IF(S$1="SIM",IF(S3="","1",VLOOKUP(S3,Dicionários!$G$2:$H$22,2,0)),"1") -> 1 | V3: =IF(U$1="SIM",IF(U3="","1",VLOOKUP(U3,Dicionários!$I$2:$J$22,2,0)),"1") -> 1 | X3: =IF(W$1="SIM",IF(W3="","1",VLOOKUP(W3,Dicionários!$K$2:$L$22,2,0)),"1") -> 1 | Y3: normal res | Z3: =IF(Y$1="SIM",IF(Y3="","1",VLOOKUP(Y3,Dicionários!$M$2:$N$12,2,0)),"1") -> 1.3 | AA3: 1 | AC3: 1º | AD3: =IF(AC$1="SIM",IF(AC3="","1",VLOOKUP(AC3,Dicionários!$O$2:$Q$22,$AD$2,0)),"1") -> 1.02 | AE3: 636000 | AF3: =IF(AE3="","",IF($AH$1="Terreno",AE3/G3,AE3/E3)) -> 6906.2873 | AG3: 0.9 | AH3: =IF(AE3="","",AF3*AG3) -> 6215.6586 | AJ3: =IF(E3="","",E3/$E$18) -> 1.0232222 | AK3: =ABS(E3-$E$18) -> 2.09 | AL3: =0.3*$E$18 -> 27 | AM3: =IF(AK3<=AL3,0.25,0.125) -> 0.25 | AO3: =IF(G3="","",G3/$G$18) | AP3: =ABS(G3-$G$18) -> 0 | AQ3: =0.3*$G$18 -> 0 | AR3: =IF(AP3<=AQ3,0.25,0.125) -> 0.25 | AT3: =IF(AND(G3>5000,K3>90),1,0) -> 0 | AU3: =IF(I3=0,1,IF(AT3=1,(4.8*(I3^2)*(G3^-0.4)),IF(K3<20,ROUND((K3/20)^0.5,3),IF(K3<33,1,IF(K3<90,ROUND((33/K3)^0.5,3),0.6))))) -> 1 | AW3: =IF(C3="",1,IF(C$1="SIM",$C$18/C3,1)) -> 1.1 | AX3: =IF(E3="",1,IF(E$1="SIM",AJ3^AM3,1)) -> 1.0057557 | AY3: =IF(G3="",1,IF(G$1="SIM",AO3^AR3,1)) -> 1 | AZ3: =IF(K3="",1,IF(K$1="SIM",$AU$18/AU3,1)) -> 1 | BA3: =IF(M$1="SIM",$N$18/N3,1) -> 1 | BB3: =IF(O$1="SIM",$P$18/P3,1) -> 1 | BC3: =IF(Q$1="SIM",$R$18/R3,1) -> 1 | BD3: =IF(S$1="SIM",$T$18/T3,1) -> 1 | BE3: =IF(U$1="SIM",$V$18/V3,1) -> 1 | BF3: =IF(W$1="SIM",$X$18/X3,1) -> 1 | BG3: =IF(Y$1="SIM",$Z$18/Z3,1) -> 1.1153846 | BH3: =IF(AA3-$AA$18=0,1,1-0.067*(AA3-$AA$18)) -> 1.067 | BI3: =IF(AC$1="SIM",$AD$18/AD3,1) -> 1.0196078 | BJ3: =1/1+((AW3-1)+(AX3-1)+(AY3-1)+(AZ3-1))+(BA3-1)+(BB3-1)+(BC3-1)+(BD3-1)+(BE3-1)+(BF3-1)+(BG3-1)+(BH3-1)+(BI3-1) -> 1.3077481 | BL3: =IF(AH3="","",BJ3*AH3) -> 8128.5159 | BM3: =IF(BL3="","",IF(BR3="Sim",AH3*BJ3,"")) -> 8128.5159 | BN3: =IF(BM3="","",ABS((BM3-$BM$18)/$BU$15)) -> 0.15912364 | BO3: =IF(BM3="","",VLOOKUP($BU$16,Dicionários!$S$2:$T$31,2,0)) -> 2.06 | BP3: =IF(BM3="","",IF(BN3>BO3,"REJEITADO","ACEITO")) -> ACEITO | BR3: Sim | BT3: Número de dados | BU3: =COUNTA(BL3:BL17) -> 15 | BW3: Área avaliando (m²): | BZ3: =IF($AH$1="Terreno",G18,E18) -> 90 | CB3: m² | CE3: Campo de Arbítrio
A4: 2 | B4: Rua E, 698 | C4: 1.1 | D4: =C4 -> 1.1 | E4: 96.05 | K4: =IF(G4="","",G4/I4) | N4: =IF(M$1="SIM",IF(M4="","1",VLOOKUP(M4,Dicionários!$A$2:$B$22,2,0)),"1") -> 1 | P4: =IF(O$1="SIM",IF(O4="","1",VLOOKUP(O4,Dicionários!$C$2:$D$22,2,0)),"1") -> 1 | R4: =IF(Q$1="SIM",IF(Q4="","1",VLOOKUP(Q4,Dicionários!$E$2:$F$22,2,0)),"1") -> 1 | T4: =IF(S$1="SIM",IF(S4="","1",VLOOKUP(S4,Dicionários!$G$2:$H$22,2,0)),"1") -> 1 | V4: =IF(U$1="SIM",IF(U4="","1",VLOOKUP(U4,Dicionários!$I$2:$J$22,2,0)),"1") -> 1 | X4: =IF(W$1="SIM",IF(W4="","1",VLOOKUP(W4,Dicionários!$K$2:$L$22,2,0)),"1") -> 1 | Y4: normal res | Z4: =IF(Y$1="SIM",IF(Y4="","1",VLOOKUP(Y4,Dicionários!$M$2:$N$12,2,0)),"1") -> 1.3 | AA4: 2 | AC4: 2º | AD4: =IF(AC$1="SIM",IF(AC4="","1",VLOOKUP(AC4,Dicionários!$O$2:$Q$22,$AD$2,0)),"1") -> 1.04 | AE4: 670000 | AF4: =IF(AE4="","",IF($AH$1="Terreno",AE4/G4,AE4/E4)) -> 6975.5336 | AG4: 0.9 | AH4: =IF(AE4="","",AF4*AG4) -> 6277.9802 | AJ4: =IF(E4="","",E4/$E$18) -> 1.0672222 | AK4: =ABS(E4-$E$18) -> 6.05 | AL4: =0.3*$E$18 -> 27 | AM4: =IF(AK4<=AL4,0.25,0.125) -> 0.25 | AO4: =IF(G4="","",G4/$G$18) | AP4: =ABS(G4-$G$18) -> 0 | AQ4: =0.3*$G$18 -> 0 | AR4: =IF(AP4<=AQ4,0.25,0.125) -> 0.25 | AT4: =IF(AND(G4>5000,K4>90),1,0) -> 0 | AU4: =IF(I4=0,1,IF(AT4=1,(4.8*(I4^2)*(G4^-0.4)),IF(K4<20,ROUND((K4/20)^0.5,3),IF(K4<33,1,IF(K4<90,ROUND((33/K4)^0.5,3),0.6))))) -> 1 | AW4: =IF(C4="",1,IF(C$1="SIM",$C$18/C4,1)) -> 1 | AX4: =IF(E4="",1,IF(E$1="SIM",AJ4^AM4,1)) -> 1.0163978 | AY4: =IF(G4="",1,IF(G$1="SIM",AO4^AR4,1)) -> 1 | AZ4: =IF(K4="",1,IF(K$1="SIM",$AU$18/AU4,1)) -> 1 | BA4: =IF(M$1="SIM",$N$18/N4,1) -> 1 | BB4: =$P$18/P4 -> 1 | BC4: =IF(Q$1="SIM",$R$18/R4,1) -> 1 | BD4: =IF(S$1="SIM",$T$18/T4,1) -> 1 | BE4: =IF(U$1="SIM",$V$18/V4,1) -> 1 | BF4: =IF(W$1="SIM",$X$18/X4,1) -> 1 | BG4: =IF(Y$1="SIM",$Z$18/Z4,1) -> 1.1153846 | BH4: =IF(AA4-$AA$18=0,1,1-0.067*(AA4-$AA$18)) -> 1 | BI4: =IF(AC$1="SIM",$AD$18/AD4,1) -> 1 | BJ4: =1/1+((AW4-1)+(AX4-1)+(AY4-1)+(AZ4-1))+(BA4-1)+(BB4-1)+(BC4-1)+(BD4-1)+(BE4-1)+(BF4-1)+(BG4-1)+(BH4-1)+(BI4-1) -> 1.1317824 | BL4: =IF(AH4="","",BJ4*AH4) -> 7105.3076 | BM4: =IF(BL4="","",IF(BR4="Sim",AH4*BJ4,"")) -> 7105.3076 | BN4: =IF(BM4="","",ABS((BM4-$BM$18)/$BU$15)) -> 1.2360336 | BO4: =IF(BM4="","",VLOOKUP($BU$16,Dicionários!$S$2:$T$31,2,0)) -> 2.06 | BP4: =IF(BM4="","",IF(BN4>BO4,"REJEITADO","ACEITO")) -> ACEITO | BR4: Sim | BT4: Média | BU4: =BL18 -> 7821.3201 | BW4: ----------------------------------------------------------------------------------- | CE4: * É basicamente é uma margem de tolerância usada em avaliações. * Essa margem é de ±15% em torno do valor estimado. * Pode ser usado quando: *O modelo de cálculo não conseguiu considerar todas as variáveis importantes; *Faltam dados de mercado; *Não existem fatores de ajuste disponíveis; *Ou algumas variáveis não mostraram relevância estatística. * A ideia é que essa margem de ±15% ajuda a compensar possíveis influências que ficaram de fora, desde que o avaliador justifique o uso.
A5: 3 | B5: Rua A | C5: 1 | D5: =C5 -> 1 | E5: 87.11 | K5: =IF(G5="","",G5/I5) | N5: =IF(M$1="SIM",IF(M5="","1",VLOOKUP(M5,Dicionários!$A$2:$B$22,2,0)),"1") -> 1 | P5: =IF(O$1="SIM",IF(O5="","1",VLOOKUP(O5,Dicionários!$C$2:$D$22,2,0)),"1") -> 1 | R5: =IF(Q$1="SIM",IF(Q5="","1",VLOOKUP(Q5,Dicionários!$E$2:$F$22,2,0)),"1") -> 1 | T5: =IF(S$1="SIM",IF(S5="","1",VLOOKUP(S5,Dicionários!$G$2:$H$22,2,0)),"1") -> 1 | V5: =IF(U$1="SIM",IF(U5="","1",VLOOKUP(U5,Dicionários!$I$2:$J$22,2,0)),"1") -> 1 | X5: =IF(W$1="SIM",IF(W5="","1",VLOOKUP(W5,Dicionários!$K$2:$L$22,2,0)),"1") -> 1 | Y5: normal res | Z5: =IF(Y$1="SIM",IF(Y5="","1",VLOOKUP(Y5,Dicionários!$M$2:$N$12,2,0)),"1") -> 1.3 | AA5: 1 | AC5: 1º | AD5: =IF(AC$1="SIM",IF(AC5="","1",VLOOKUP(AC5,Dicionários!$O$2:$Q$22,$AD$2,0)),"1") -> 1.02 | AE5: 636000 | AF5: =IF(AE5="","",IF($AH$1="Terreno",AE5/G5,AE5/E5)) -> 7301.1135 | AG5: 0.9 | AH5: =IF(AE5="","",AF5*AG5) -> 6571.0022 | AJ5: =IF(E5="","",E5/$E$18) -> 0.96788889 | AK5: =ABS(E5-$E$18) -> 2.89 | AL5: =0.3*$E$18 -> 27 | AM5: =IF(AK5<=AL5,0.25,0.125) -> 0.25 | AO5: =IF(G5="","",G5/$G$18) | AP5: =ABS(G5-$G$18) -> 0 | AQ5: =0.3*$G$18 -> 0 | AR5: =IF(AP5<=AQ5,0.25,0.125) -> 0.25 | AT5: =IF(AND(G5>5000,K5>90),1,0) -> 0 | AU5: =IF(I5=0,1,IF(AT5=1,(4.8*(I5^2)*(G5^-0.4)),IF(K5<20,ROUND((K5/20)^0.5,3),IF(K5<33,1,IF(K5<90,ROUND((33/K5)^0.5,3),0.6))))) -> 1 | AW5: =IF(C5="",1,IF(C$1="SIM",$C$18/C5,1)) -> 1.1 | AX5: =IF(E5="",1,IF(E$1="SIM",AJ5^AM5,1)) -> 0.9918737 | AY5: =IF(G5="",1,IF(G$1="SIM",AO5^AR5,1)) -> 1 | AZ5: =IF(K5="",1,IF(K$1="SIM",$AU$18/AU5,1)) -> 1 | BA5: =IF(M$1="SIM",$N$18/N5,1) -> 1 | BB5: =$P$18/P5 -> 1 | BC5: =IF(Q$1="SIM",$R$18/R5,1) -> 1 | BD5: =IF(S$1="SIM",$T$18/T5,1) -> 1 | BE5: =IF(U$1="SIM",$V$18/V5,1) -> 1 | BF5: =IF(W$1="SIM",$X$18/X5,1) -> 1 | BG5: =IF(Y$1="SIM",$Z$18/Z5,1) -> 1.1153846 | BH5: =IF(AA5-$AA$18=0,1,1-0.067*(AA5-$AA$18)) -> 1.067 | BI5: =IF(AC$1="SIM",$AD$18/AD5,1) -> 1.0196078 | BJ5: =1/1+((AW5-1)+(AX5-1)+(AY5-1)+(AZ5-1))+(BA5-1)+(BB5-1)+(BC5-1)+(BD5-1)+(BE5-1)+(BF5-1)+(BG5-1)+(BH5-1)+(BI5-1) -> 1.2938662 | BL5: =IF(AH5="","",BJ5*AH5) -> 8501.9974 | BM5: =IF(BL5="","",IF(BR5="Sim",AH5*BJ5,"")) -> 8501.9974 | BN5: =IF(BM5="","",ABS((BM5-$BM$18)/$BU$15)) -> 0.66837025 | BO5: =IF(BM5="","",VLOOKUP($BU$16,Dicionários!$S$2:$T$31,2,0)) -> 2.06 | BP5: =IF(BM5="","",IF(BN5>BO5,"REJEITADO","ACEITO")) -> ACEITO | BR5: Sim | BT5: Graus de liberdade (n-1) | BU5: =BU3-1 -> 14 | BW5: Valores Unitários (R$/m²)
A6: 4 | B6: Rua G, 66 | C6: 1.1 | D6: =C6 -> 1.1 | E6: 95.02 | K6: =IF(G6="","",G6/I6) | N6: =IF(M$1="SIM",IF(M6="","1",VLOOKUP(M6,Dicionários!$A$2:$B$22,2,0)),"1") -> 1 | P6: =IF(O$1="SIM",IF(O6="","1",VLOOKUP(O6,Dicionários!$C$2:$D$22,2,0)),"1") -> 1 | R6: =IF(Q$1="SIM",IF(Q6="","1",VLOOKUP(Q6,Dicionários!$E$2:$F$22,2,0)),"1") -> 1 | T6: =IF(S$1="SIM",IF(S6="","1",VLOOKUP(S6,Dicionários!$G$2:$H$22,2,0)),"1") -> 1 | V6: =IF(U$1="SIM",IF(U6="","1",VLOOKUP(U6,Dicionários!$I$2:$J$22,2,0)),"1") -> 1 | X6: =IF(W$1="SIM",IF(W6="","1",VLOOKUP(W6,Dicionários!$K$2:$L$22,2,0)),"1") -> 1 | Y6: alto res | Z6: =IF(Y$1="SIM",IF(Y6="","1",VLOOKUP(Y6,Dicionários!$M$2:$N$12,2,0)),"1") -> 1.45 | AA6: 1 | AC6: 3º | AD6: =IF(AC$1="SIM",IF(AC6="","1",VLOOKUP(AC6,Dicionários!$O$2:$Q$22,$AD$2,0)),"1") -> 1.061 | AE6: 742000 | AF6: =IF(AE6="","",IF($AH$1="Terreno",AE6/G6,AE6/E6)) -> 7808.8823 | AG6: 0.9 | AH6: =IF(AE6="","",AF6*AG6) -> 7027.9941 | AJ6: =IF(E6="","",E6/$E$18) -> 1.0557778 | AK6: =ABS(E6-$E$18) -> 5.02 | AL6: =0.3*$E$18 -> 27 | AM6: =IF(AK6<=AL6,0.25,0.125) -> 0.25 | AO6: =IF(G6="","",G6/$G$18) | AP6: =ABS(G6-$G$18) -> 0 | AQ6: =0.3*$G$18 -> 0 | AR6: =IF(AP6<=AQ6,0.25,0.125) -> 0.25 | AT6: =IF(AND(G6>5000,K6>90),1,0) -> 0 | AU6: =IF(I6=0,1,IF(AT6=1,(4.8*(I6^2)*(G6^-0.4)),IF(K6<20,ROUND((K6/20)^0.5,3),IF(K6<33,1,IF(K6<90,ROUND((33/K6)^0.5,3),0.6))))) -> 1 | AW6: =IF(C6="",1,IF(C$1="SIM",$C$18/C6,1)) -> 1 | AX6: =IF(E6="",1,IF(E$1="SIM",AJ6^AM6,1)) -> 1.0136619 | AY6: =IF(G6="",1,IF(G$1="SIM",AO6^AR6,1)) -> 1 | AZ6: =IF(K6="",1,IF(K$1="SIM",$AU$18/AU6,1)) -> 1 | BA6: =IF(M$1="SIM",$N$18/N6,1) -> 1 | BB6: =$P$18/P6 -> 1 | BC6: =IF(Q$1="SIM",$R$18/R6,1) -> 1 | BD6: =IF(S$1="SIM",$T$18/T6,1) -> 1 | BE6: =IF(U$1="SIM",$V$18/V6,1) -> 1 | BF6: =IF(W$1="SIM",$X$18/X6,1) -> 1 | BG6: =IF(Y$1="SIM",$Z$18/Z6,1) -> 1 | BH6: =IF(AA6-$AA$18=0,1,1-0.067*(AA6-$AA$18)) -> 1.067 | BI6: =IF(AC$1="SIM",$AD$18/AD6,1) -> 0.98020735 | BJ6: =1/1+((AW6-1)+(AX6-1)+(AY6-1)+(AZ6-1))+(BA6-1)+(BB6-1)+(BC6-1)+(BD6-1)+(BE6-1)+(BF6-1)+(BG6-1)+(BH6-1)+(BI6-1) -> 1.0608693 | BL6: =IF(AH6="","",BJ6*AH6) -> 7455.7829 | BM6: =IF(BL6="","",IF(BR6="Sim",AH6*BJ6,"")) -> 7455.7829 | BN6: =IF(BM6="","",ABS((BM6-$BM$18)/$BU$15)) -> 0.75815613 | BO6: =IF(BM6="","",VLOOKUP($BU$16,Dicionários!$S$2:$T$31,2,0)) -> 2.06 | BP6: =IF(BM6="","",IF(BN6>BO6,"REJEITADO","ACEITO")) -> ACEITO | BR6: Sim | BT6: Valor máximo | BU6: =LARGE($BL$3:$BL$17,1) -> 9289.6498 | BW6: Médio estimado | BZ6: =BU14 -> 8011.8146
A7: 5 | B7: Rua C, 161 | C7: 1.1 | D7: =C7 -> 1.1 | E7: 88.14 | K7: =IF(G7="","",G7/I7) | N7: =IF(M$1="SIM",IF(M7="","1",VLOOKUP(M7,Dicionários!$A$2:$B$22,2,0)),"1") -> 1 | P7: =IF(O$1="SIM",IF(O7="","1",VLOOKUP(O7,Dicionários!$C$2:$D$22,2,0)),"1") -> 1 | R7: =IF(Q$1="SIM",IF(Q7="","1",VLOOKUP(Q7,Dicionários!$E$2:$F$22,2,0)),"1") -> 1 | T7: =IF(S$1="SIM",IF(S7="","1",VLOOKUP(S7,Dicionários!$G$2:$H$22,2,0)),"1") -> 1 | V7: =IF(U$1="SIM",IF(U7="","1",VLOOKUP(U7,Dicionários!$I$2:$J$22,2,0)),"1") -> 1 | X7: =IF(W$1="SIM",IF(W7="","1",VLOOKUP(W7,Dicionários!$K$2:$L$22,2,0)),"1") -> 1 | Y7: alto res | Z7: =IF(Y$1="SIM",IF(Y7="","1",VLOOKUP(Y7,Dicionários!$M$2:$N$12,2,0)),"1") -> 1.45 | AA7: 1 | AC7: 3º | AD7: =IF(AC$1="SIM",IF(AC7="","1",VLOOKUP(AC7,Dicionários!$O$2:$Q$22,$AD$2,0)),"1") -> 1.061 | AE7: 696150 | AF7: =IF(AE7="","",IF($AH$1="Terreno",AE7/G7,AE7/E7)) -> 7898.2301 | AG7: 0.9 | AH7: =IF(AE7="","",AF7*AG7) -> 7108.4071 | AJ7: =IF(E7="","",E7/$E$18) -> 0.97933333 | AK7: =ABS(E7-$E$18) -> 1.86 | AL7: =0.3*$E$18 -> 27 | AM7: =IF(AK7<=AL7,0.25,0.125) -> 0.25 | AO7: =IF(G7="","",G7/$G$18) | AP7: =ABS(G7-$G$18) -> 0 | AQ7: =0.3*$G$18 -> 0 | AR7: =IF(AP7<=AQ7,0.25,0.125) -> 0.25 | AT7: =IF(AND(G7>5000,K7>90),1,0) -> 0 | AU7: =IF(I7=0,1,IF(AT7=1,(4.8*(I7^2)*(G7^-0.4)),IF(K7<20,ROUND((K7/20)^0.5,3),IF(K7<33,1,IF(K7<90,ROUND((33/K7)^0.5,3),0.6))))) -> 1 | AW7: =IF(C7="",1,IF(C$1="SIM",$C$18/C7,1)) -> 1 | AX7: =IF(E7="",1,IF(E$1="SIM",AJ7^AM7,1)) -> 0.9947928 | AY7: =IF(G7="",1,IF(G$1="SIM",AO7^AR7,1)) -> 1 | AZ7: =IF(K7="",1,IF(K$1="SIM",$AU$18/AU7,1)) -> 1 | BA7: =IF(M$1="SIM",$N$18/N7,1) -> 1 | BB7: =$P$18/P7 -> 1 | BC7: =IF(Q$1="SIM",$R$18/R7,1) -> 1 | BD7: =IF(S$1="SIM",$T$18/T7,1) -> 1 | BE7: =IF(U$1="SIM",$V$18/V7,1) -> 1 | BF7: =IF(W$1="SIM",$X$18/X7,1) -> 1 | BG7: =IF(Y$1="SIM",$Z$18/Z7,1) -> 1 | BH7: =IF(AA7-$AA$18=0,1,1-0.067*(AA7-$AA$18)) -> 1.067 | BI7: =IF(AC$1="SIM",$AD$18/AD7,1) -> 0.98020735 | BJ7: =1/1+((AW7-1)+(AX7-1)+(AY7-1)+(AZ7-1))+(BA7-1)+(BB7-1)+(BC7-1)+(BD7-1)+(BE7-1)+(BF7-1)+(BG7-1)+(BH7-1)+(BI7-1) -> 1.0420002 | BL7: =IF(AH7="","",BJ7*AH7) -> 7406.9613 | BM7: =IF(BL7="","",IF(BR7="Sim",AH7*BJ7,"")) -> 7406.9613 | BN7: =IF(BM7="","",ABS((BM7-$BM$18)/$BU$15)) -> 0.8247251 | BO7: =IF(BM7="","",VLOOKUP($BU$16,Dicionários!$S$2:$T$31,2,0)) -> 2.06 | BP7: =IF(BM7="","",IF(BN7>BO7,"REJEITADO","ACEITO")) -> ACEITO | BR7: Sim | BT7: Valor mínimo | BU7: =SMALL($BL$3:$BL$17,1) -> 5154.3972 | BW7: LI Campo de Arbítrio (-15%) | BZ7: =BU18 -> 6810.0424
A8: 6 | B8: Rua B, 00 | C8: 1.1 | D8: =C8 -> 1.1 | E8: 81.43 | K8: =IF(G8="","",G8/I8) | N8: =IF(M$1="SIM",IF(M8="","1",VLOOKUP(M8,Dicionários!$A$2:$B$22,2,0)),"1") -> 1 | P8: =IF(O$1="SIM",IF(O8="","1",VLOOKUP(O8,Dicionários!$C$2:$D$22,2,0)),"1") -> 1 | R8: =IF(Q$1="SIM",IF(Q8="","1",VLOOKUP(Q8,Dicionários!$E$2:$F$22,2,0)),"1") -> 1 | T8: =IF(S$1="SIM",IF(S8="","1",VLOOKUP(S8,Dicionários!$G$2:$H$22,2,0)),"1") -> 1 | V8: =IF(U$1="SIM",IF(U8="","1",VLOOKUP(U8,Dicionários!$I$2:$J$22,2,0)),"1") -> 1 | X8: =IF(W$1="SIM",IF(W8="","1",VLOOKUP(W8,Dicionários!$K$2:$L$22,2,0)),"1") -> 1 | Y8: alto res | Z8: =IF(Y$1="SIM",IF(Y8="","1",VLOOKUP(Y8,Dicionários!$M$2:$N$12,2,0)),"1") -> 1.45 | AA8: 1 | AC8: 2º | AD8: =IF(AC$1="SIM",IF(AC8="","1",VLOOKUP(AC8,Dicionários!$O$2:$Q$22,$AD$2,0)),"1") -> 1.04 | AE8: 650000 | AF8: =IF(AE8="","",IF($AH$1="Terreno",AE8/G8,AE8/E8)) -> 7982.3161 | AG8: 0.9 | AH8: =IF(AE8="","",AF8*AG8) -> 7184.0845 | AJ8: =IF(E8="","",E8/$E$18) -> 0.90477778 | AK8: =ABS(E8-$E$18) -> 8.57 | AL8: =0.3*$E$18 -> 27 | AM8: =IF(AK8<=AL8,0.25,0.125) -> 0.25 | AO8: =IF(G8="","",G8/$G$18) | AP8: =ABS(G8-$G$18) -> 0 | AQ8: =0.3*$G$18 -> 0 | AR8: =IF(AP8<=AQ8,0.25,0.125) -> 0.25 | AT8: =IF(AND(G8>5000,K8>90),1,0) -> 0 | AU8: =IF(I8=0,1,IF(AT8=1,(4.8*(I8^2)*(G8^-0.4)),IF(K8<20,ROUND((K8/20)^0.5,3),IF(K8<33,1,IF(K8<90,ROUND((33/K8)^0.5,3),0.6))))) -> 1 | AW8: =IF(C8="",1,IF(C$1="SIM",$C$18/C8,1)) -> 1 | AX8: =IF(E8="",1,IF(E$1="SIM",AJ8^AM8,1)) -> 0.97529384 | AY8: =IF(G8="",1,IF(G$1="SIM",AO8^AR8,1)) -> 1 | AZ8: =IF(K8="",1,IF(K$1="SIM",$AU$18/AU8,1)) -> 1 | BA8: =IF(M$1="SIM",$N$18/N8,1) -> 1 | BB8: =$P$18/P8 -> 1 | BC8: =IF(Q$1="SIM",$R$18/R8,1) -> 1 | BD8: =IF(S$1="SIM",$T$18/T8,1) -> 1 | BE8: =IF(U$1="SIM",$V$18/V8,1) -> 1 | BF8: =IF(W$1="SIM",$X$18/X8,1) -> 1 | BG8: =IF(Y$1="SIM",$Z$18/Z8,1) -> 1 | BH8: =IF(AA8-$AA$18=0,1,1-0.067*(AA8-$AA$18)) -> 1.067 | BI8: =IF(AC$1="SIM",$AD$18/AD8,1) -> 1 | BJ8: =1/1+((AW8-1)+(AX8-1)+(AY8-1)+(AZ8-1))+(BA8-1)+(BB8-1)+(BC8-1)+(BD8-1)+(BE8-1)+(BF8-1)+(BG8-1)+(BH8-1)+(BI8-1) -> 1.0422938 | BL8: =IF(AH8="","",BJ8*AH8) -> 7487.927 | BM8: =IF(BL8="","",IF(BR8="Sim",AH8*BJ8,"")) -> 7487.927 | BN8: =IF(BM8="","",ABS((BM8-$BM$18)/$BU$15)) -> 0.7143273 | BO8: =IF(BM8="","",VLOOKUP($BU$16,Dicionários!$S$2:$T$31,2,0)) -> 2.06 | BP8: =IF(BM8="","",IF(BN8>BO8,"REJEITADO","ACEITO")) -> ACEITO | BR8: Sim | BT8: Limite superior (1,15 * média) | BU8: =1.15*$BU$4 -> 8994.5182 | BW8: LS Campo de Arbítrio (+15%) | BZ8: =BU17 -> 9213.5868
A9: 7 | B9: Rua C, 161 | C9: 1.1 | D9: =C9 -> 1.1 | E9: 88.14 | K9: =IF(G9="","",G9/I9) | N9: =IF(M$1="SIM",IF(M9="","1",VLOOKUP(M9,Dicionários!$A$2:$B$22,2,0)),"1") -> 1 | P9: =IF(O$1="SIM",IF(O9="","1",VLOOKUP(O9,Dicionários!$C$2:$D$22,2,0)),"1") -> 1 | R9: =IF(Q$1="SIM",IF(Q9="","1",VLOOKUP(Q9,Dicionários!$E$2:$F$22,2,0)),"1") -> 1 | T9: =IF(S$1="SIM",IF(S9="","1",VLOOKUP(S9,Dicionários!$G$2:$H$22,2,0)),"1") -> 1 | V9: =IF(U$1="SIM",IF(U9="","1",VLOOKUP(U9,Dicionários!$I$2:$J$22,2,0)),"1") -> 1 | X9: =IF(W$1="SIM",IF(W9="","1",VLOOKUP(W9,Dicionários!$K$2:$L$22,2,0)),"1") -> 1 | Y9: alto res | Z9: =IF(Y$1="SIM",IF(Y9="","1",VLOOKUP(Y9,Dicionários!$M$2:$N$12,2,0)),"1") -> 1.45 | AA9: 1 | AC9: 4º | AD9: =IF(AC$1="SIM",IF(AC9="","1",VLOOKUP(AC9,Dicionários!$O$2:$Q$22,$AD$2,0)),"1") -> 1.082 | AE9: 703800 | AF9: =IF(AE9="","",IF($AH$1="Terreno",AE9/G9,AE9/E9)) -> 7985.0238 | AG9: 0.9 | AH9: =IF(AE9="","",AF9*AG9) -> 7186.5214 | AJ9: =IF(E9="","",E9/$E$18) -> 0.97933333 | AK9: =ABS(E9-$E$18) -> 1.86 | AL9: =0.3*$E$18 -> 27 | AM9: =IF(AK9<=AL9,0.25,0.125) -> 0.25 | AO9: =IF(G9="","",G9/$G$18) | AP9: =ABS(G9-$G$18) -> 0 | AQ9: =0.3*$G$18 -> 0 | AR9: =IF(AP9<=AQ9,0.25,0.125) -> 0.25 | AT9: =IF(AND(G9>5000,K9>90),1,0) -> 0 | AU9: =IF(I9=0,1,IF(AT9=1,(4.8*(I9^2)*(G9^-0.4)),IF(K9<20,ROUND((K9/20)^0.5,3),IF(K9<33,1,IF(K9<90,ROUND((33/K9)^0.5,3),0.6))))) -> 1 | AW9: =IF(C9="",1,IF(C$1="SIM",$C$18/C9,1)) -> 1 | AX9: =IF(E9="",1,IF(E$1="SIM",AJ9^AM9,1)) -> 0.9947928 | AY9: =IF(G9="",1,IF(G$1="SIM",AO9^AR9,1)) -> 1 | AZ9: =IF(K9="",1,IF(K$1="SIM",$AU$18/AU9,1)) -> 1 | BA9: =IF(M$1="SIM",$N$18/N9,1) -> 1 | BB9: =$P$18/P9 -> 1 | BC9: =IF(Q$1="SIM",$R$18/R9,1) -> 1 | BD9: =IF(S$1="SIM",$T$18/T9,1) -> 1 | BE9: =IF(U$1="SIM",$V$18/V9,1) -> 1 | BF9: =IF(W$1="SIM",$X$18/X9,1) -> 1 | BG9: =IF(Y$1="SIM",$Z$18/Z9,1) -> 1 | BH9: =IF(AA9-$AA$18=0,1,1-0.067*(AA9-$AA$18)) -> 1.067 | BI9: =IF(AC$1="SIM",$AD$18/AD9,1) -> 0.96118299 | BJ9: =1/1+((AW9-1)+(AX9-1)+(AY9-1)+(AZ9-1))+(BA9-1)+(BB9-1)+(BC9-1)+(BD9-1)+(BE9-1)+(BF9-1)+(BG9-1)+(BH9-1)+(BI9-1) -> 1.0229758 | BL9: =IF(AH9="","",BJ9*AH9) -> 7351.6375 | BM9: =IF(BL9="","",IF(BR9="Sim",AH9*BJ9,"")) -> 7351.6375 | BN9: =IF(BM9="","",ABS((BM9-$BM$18)/$BU$15)) -> 0.90015975 | BO9: =IF(BM9="","",VLOOKUP($BU$16,Dicionários!$S$2:$T$31,2,0)) -> 2.06 | BP9: =IF(BM9="","",IF(BN9>BO9,"REJEITADO","ACEITO")) -> ACEITO | BR9: Sim | BT9: Limite inferior (0,85 * média) | BU9: =0.85*$BU$4 -> 6648.1221 | BW9: LI Intevalo de Confiança 80% | BZ9: =BU20 -> 7737.2131
A10: 8 | B10: Rua C, 161 | C10: 1.1 | D10: =C10 -> 1.1 | E10: 88.14 | K10: =IF(G10="","",G10/I10) | N10: =IF(M$1="SIM",IF(M10="","1",VLOOKUP(M10,Dicionários!$A$2:$B$22,2,0)),"1") -> 1 | P10: =IF(O$1="SIM",IF(O10="","1",VLOOKUP(O10,Dicionários!$C$2:$D$22,2,0)),"1") -> 1 | R10: =IF(Q$1="SIM",IF(Q10="","1",VLOOKUP(Q10,Dicionários!$E$2:$F$22,2,0)),"1") -> 1 | T10: =IF(S$1="SIM",IF(S10="","1",VLOOKUP(S10,Dicionários!$G$2:$H$22,2,0)),"1") -> 1 | V10: =IF(U$1="SIM",IF(U10="","1",VLOOKUP(U10,Dicionários!$I$2:$J$22,2,0)),"1") -> 1 | X10: =IF(W$1="SIM",IF(W10="","1",VLOOKUP(W10,Dicionários!$K$2:$L$22,2,0)),"1") -> 1 | Y10: alto res | Z10: =IF(Y$1="SIM",IF(Y10="","1",VLOOKUP(Y10,Dicionários!$M$2:$N$12,2,0)),"1") -> 1.45 | AA10: 1 | AC10: 4º | AD10: =IF(AC$1="SIM",IF(AC10="","1",VLOOKUP(AC10,Dicionários!$O$2:$Q$22,$AD$2,0)),"1") -> 1.082 | AE10: 710736 | AF10: =IF(AE10="","",IF($AH$1="Terreno",AE10/G10,AE10/E10)) -> 8063.7168 | AG10: 0.9 | AH10: =IF(AE10="","",AF10*AG10) -> 7257.3451 | AJ10: =IF(E10="","",E10/$E$18) -> 0.97933333 | AK10: =ABS(E10-$E$18) -> 1.86 | AL10: =0.3*$E$18 -> 27 | AM10: =IF(AK10<=AL10,0.25,0.125) -> 0.25 | AO10: =IF(G10="","",G10/$G$18) | AP10: =ABS(G10-$G$18) -> 0 | AQ10: =0.3*$G$18 -> 0 | AR10: =IF(AP10<=AQ10,0.25,0.125) -> 0.25 | AT10: =IF(AND(G10>5000,K10>90),1,0) -> 0 | AU10: =IF(I10=0,1,IF(AT10=1,(4.8*(I10^2)*(G10^-0.4)),IF(K10<20,ROUND((K10/20)^0.5,3),IF(K10<33,1,IF(K10<90,ROUND((33/K10)^0.5,3),0.6))))) -> 1 | AW10: =IF(C10="",1,IF(C$1="SIM",$C$18/C10,1)) -> 1 | AX10: =IF(E10="",1,IF(E$1="SIM",AJ10^AM10,1)) -> 0.9947928 | AY10: =IF(G10="",1,IF(G$1="SIM",AO10^AR10,1)) -> 1 | AZ10: =IF(K10="",1,IF(K$1="SIM",$AU$18/AU10,1)) -> 1 | BA10: =IF(M$1="SIM",$N$18/N10,1) -> 1 | BB10: =$P$18/P10 -> 1 | BC10: =IF(Q$1="SIM",$R$18/R10,1) -> 1 | BD10: =IF(S$1="SIM",$T$18/T10,1) -> 1 | BE10: =IF(U$1="SIM",$V$18/V10,1) -> 1 | BF10: =IF(W$1="SIM",$X$18/X10,1) -> 1 | BG10: =IF(Y$1="SIM",$Z$18/Z10,1) -> 1 | BH10: =IF(AA10-$AA$18=0,1,1-0.067*(AA10-$AA$18)) -> 1.067 | BI10: =IF(AC$1="SIM",$AD$18/AD10,1) -> 0.96118299 | BJ10: =1/1+((AW10-1)+(AX10-1)+(AY10-1)+(AZ10-1))+(BA10-1)+(BB10-1)+(BC10-1)+(BD10-1)+(BE10-1)+(BF10-1)+(BG10-1)+(BH10-1)+(BI10-1) -> 1.0229758 | BL10: =IF(AH10="","",BJ10*AH10) -> 7424.0884 | BM10: =IF(BL10="","",IF(BR10="Sim",AH10*BJ10,"")) -> 7424.0884 | BN10: =IF(BM10="","",ABS((BM10-$BM$18)/$BU$15)) -> 0.80137202 | BO10: =IF(BM10="","",VLOOKUP($BU$16,Dicionários!$S$2:$T$31,2,0)) -> 2.06 | BP10: =IF(BM10="","",IF(BN10>BO10,"REJEITADO","ACEITO")) -> ACEITO | BR10: Sim | BT10: Desvio padrão | BU10: =STDEV($BL$3:$BL$17) -> 1021.6546 | BW10: LS Intevalo de Confiança 80% | BZ10: =BU21 -> 8286.4162
A11: 9 | B11: Rua C, 161 | C11: 1.1 | D11: =C11 -> 1.1 | E11: 88.14 | K11: =IF(G11="","",G11/I11) | N11: =IF(M$1="SIM",IF(M11="","1",VLOOKUP(M11,Dicionários!$A$2:$B$22,2,0)),"1") -> 1 | P11: =IF(O$1="SIM",IF(O11="","1",VLOOKUP(O11,Dicionários!$C$2:$D$22,2,0)),"1") -> 1 | R11: =IF(Q$1="SIM",IF(Q11="","1",VLOOKUP(Q11,Dicionários!$E$2:$F$22,2,0)),"1") -> 1 | T11: =IF(S$1="SIM",IF(S11="","1",VLOOKUP(S11,Dicionários!$G$2:$H$22,2,0)),"1") -> 1 | V11: =IF(U$1="SIM",IF(U11="","1",VLOOKUP(U11,Dicionários!$I$2:$J$22,2,0)),"1") -> 1 | X11: =IF(W$1="SIM",IF(W11="","1",VLOOKUP(W11,Dicionários!$K$2:$L$22,2,0)),"1") -> 1 | Y11: alto res | Z11: =IF(Y$1="SIM",IF(Y11="","1",VLOOKUP(Y11,Dicionários!$M$2:$N$12,2,0)),"1") -> 1.45 | AA11: 1 | AC11: 5º | AD11: =IF(AC$1="SIM",IF(AC11="","1",VLOOKUP(AC11,Dicionários!$O$2:$Q$22,$AD$2,0)),"1") -> 1.104 | AE11: 728222.8 | AF11: =IF(AE11="","",IF($AH$1="Terreno",AE11/G11,AE11/E11)) -> 8262.1148 | AG11: 0.9 | AH11: =IF(AE11="","",AF11*AG11) -> 7435.9033 | AJ11: =IF(E11="","",E11/$E$18) -> 0.97933333 | AK11: =ABS(E11-$E$18) -> 1.86 | AL11: =0.3*$E$18 -> 27 | AM11: =IF(AK11<=AL11,0.25,0.125) -> 0.25 | AO11: =IF(G11="","",G11/$G$18) | AP11: =ABS(G11-$G$18) -> 0 | AQ11: =0.3*$G$18 -> 0 | AR11: =IF(AP11<=AQ11,0.25,0.125) -> 0.25 | AT11: =IF(AND(G11>5000,K11>90),1,0) -> 0 | AU11: =IF(I11=0,1,IF(AT11=1,(4.8*(I11^2)*(G11^-0.4)),IF(K11<20,ROUND((K11/20)^0.5,3),IF(K11<33,1,IF(K11<90,ROUND((33/K11)^0.5,3),0.6))))) -> 1 | AW11: =IF(C11="",1,IF(C$1="SIM",$C$18/C11,1)) -> 1 | AX11: =IF(E11="",1,IF(E$1="SIM",AJ11^AM11,1)) -> 0.9947928 | AY11: =IF(G11="",1,IF(G$1="SIM",AO11^AR11,1)) -> 1 | AZ11: =IF(K11="",1,IF(K$1="SIM",$AU$18/AU11,1)) -> 1 | BA11: =IF(M$1="SIM",$N$18/N11,1) -> 1 | BB11: =$P$18/P11 -> 1 | BC11: =IF(Q$1="SIM",$R$18/R11,1) -> 1 | BD11: =IF(S$1="SIM",$T$18/T11,1) -> 1 | BE11: =IF(U$1="SIM",$V$18/V11,1) -> 1 | BF11: =IF(W$1="SIM",$X$18/X11,1) -> 1 | BG11: =IF(Y$1="SIM",$Z$18/Z11,1) -> 1 | BH11: =IF(AA11-$AA$18=0,1,1-0.067*(AA11-$AA$18)) -> 1.067 | BI11: =IF(AC$1="SIM",$AD$18/AD11,1) -> 0.94202899 | BJ11: =1/1+((AW11-1)+(AX11-1)+(AY11-1)+(AZ11-1))+(BA11-1)+(BB11-1)+(BC11-1)+(BD11-1)+(BE11-1)+(BF11-1)+(BG11-1)+(BH11-1)+(BI11-1) -> 1.0038218 | BL11: =IF(AH11="","",BJ11*AH11) -> 7464.3218 | BM11: =IF(BL11="","",IF(BR11="Sim",AH11*BJ11,"")) -> 7464.3218 | BN11: =IF(BM11="","",ABS((BM11-$BM$18)/$BU$15)) -> 0.74651333 | BO11: =IF(BM11="","",VLOOKUP($BU$16,Dicionários!$S$2:$T$31,2,0)) -> 2.06 | BP11: =IF(BM11="","",IF(BN11>BO11,"REJEITADO","ACEITO")) -> ACEITO | BR11: Sim | BT11: Coeficiente de variação | BU11: =BU10/BU4 -> 0.13062432 | BW11: -----------------------------------------------------------------------------------
A12: 10 | B12: Rua D, 475 | C12: 1.1 | D12: =C12 -> 1.1 | E12: 84.93 | K12: =IF(G12="","",G12/I12) | N12: =IF(M$1="SIM",IF(M12="","1",VLOOKUP(M12,Dicionários!$A$2:$B$22,2,0)),"1") -> 1 | P12: =IF(O$1="SIM",IF(O12="","1",VLOOKUP(O12,Dicionários!$C$2:$D$22,2,0)),"1") -> 1 | R12: =IF(Q$1="SIM",IF(Q12="","1",VLOOKUP(Q12,Dicionários!$E$2:$F$22,2,0)),"1") -> 1 | T12: =IF(S$1="SIM",IF(S12="","1",VLOOKUP(S12,Dicionários!$G$2:$H$22,2,0)),"1") -> 1 | V12: =IF(U$1="SIM",IF(U12="","1",VLOOKUP(U12,Dicionários!$I$2:$J$22,2,0)),"1") -> 1 | X12: =IF(W$1="SIM",IF(W12="","1",VLOOKUP(W12,Dicionários!$K$2:$L$22,2,0)),"1") -> 1 | Y12: alto res | Z12: =IF(Y$1="SIM",IF(Y12="","1",VLOOKUP(Y12,Dicionários!$M$2:$N$12,2,0)),"1") -> 1.45 | AA12: 1 | AC12: 2º | AD12: =IF(AC$1="SIM",IF(AC12="","1",VLOOKUP(AC12,Dicionários!$O$2:$Q$22,$AD$2,0)),"1") -> 1.04 | AE12: 710200 | AF12: =IF(AE12="","",IF($AH$1="Terreno",AE12/G12,AE12/E12)) -> 8362.1806 | AG12: 0.9 | AH12: =IF(AE12="","",AF12*AG12) -> 7525.9626 | AJ12: =IF(E12="","",E12/$E$18) -> 0.94366667 | AK12: =ABS(E12-$E$18) -> 5.07 | AL12: =0.3*$E$18 -> 27 | AM12: =IF(AK12<=AL12,0.25,0.125) -> 0.25 | AO12: =IF(G12="","",G12/$G$18) | AP12: =ABS(G12-$G$18) -> 0 | AQ12: =0.3*$G$18 -> 0 | AR12: =IF(AP12<=AQ12,0.25,0.125) -> 0.25 | AT12: =IF(AND(G12>5000,K12>90),1,0) -> 0 | AU12: =IF(I12=0,1,IF(AT12=1,(4.8*(I12^2)*(G12^-0.4)),IF(K12<20,ROUND((K12/20)^0.5,3),IF(K12<33,1,IF(K12<90,ROUND((33/K12)^0.5,3),0.6))))) -> 1 | AW12: =IF(C12="",1,IF(C$1="SIM",$C$18/C12,1)) -> 1 | AX12: =IF(E12="",1,IF(E$1="SIM",AJ12^AM12,1)) -> 0.98560898 | AY12: =IF(G12="",1,IF(G$1="SIM",AO12^AR12,1)) -> 1 | AZ12: =IF(K12="",1,IF(K$1="SIM",$AU$18/AU12,1)) -> 1 | BA12: =IF(M$1="SIM",$N$18/N12,1) -> 1 | BB12: =$P$18/P12 -> 1 | BC12: =IF(Q$1="SIM",$R$18/R12,1) -> 1 | BD12: =IF(S$1="SIM",$T$18/T12,1) -> 1 | BE12: =IF(U$1="SIM",$V$18/V12,1) -> 1 | BF12: =IF(W$1="SIM",$X$18/X12,1) -> 1 | BG12: =IF(Y$1="SIM",$Z$18/Z12,1) -> 1 | BH12: =IF(AA12-$AA$18=0,1,1-0.067*(AA12-$AA$18)) -> 1.067 | BI12: =IF(AC$1="SIM",$AD$18/AD12,1) -> 1 | BJ12: =1/1+((AW12-1)+(AX12-1)+(AY12-1)+(AZ12-1))+(BA12-1)+(BB12-1)+(BC12-1)+(BD12-1)+(BE12-1)+(BF12-1)+(BG12-1)+(BH12-1)+(BI12-1) -> 1.052609 | BL12: =IF(AH12="","",BJ12*AH12) -> 7921.8958 | BM12: =IF(BL12="","",IF(BR12="Sim",AH12*BJ12,"")) -> 7921.8958 | BN12: =IF(BM12="","",ABS((BM12-$BM$18)/$BU$15)) -> 0.12260545 | BO12: =IF(BM12="","",VLOOKUP($BU$16,Dicionários!$S$2:$T$31,2,0)) -> 2.06 | BP12: =IF(BM12="","",IF(BN12>BO12,"REJEITADO","ACEITO")) -> ACEITO | BR12: Sim | BT12: Estatísticas após saneamento | BW12: Valores Totais (R$/m²)
A13: 11 | B13: Rua F, 550 | C13: 1 | D13: =C13 -> 1 | E13: 97.94 | K13: =IF(G13="","",G13/I13) | N13: =IF(M$1="SIM",IF(M13="","1",VLOOKUP(M13,Dicionários!$A$2:$B$22,2,0)),"1") -> 1 | P13: =IF(O$1="SIM",IF(O13="","1",VLOOKUP(O13,Dicionários!$C$2:$D$22,2,0)),"1") -> 1 | R13: =IF(Q$1="SIM",IF(Q13="","1",VLOOKUP(Q13,Dicionários!$E$2:$F$22,2,0)),"1") -> 1 | T13: =IF(S$1="SIM",IF(S13="","1",VLOOKUP(S13,Dicionários!$G$2:$H$22,2,0)),"1") -> 1 | V13: =IF(U$1="SIM",IF(U13="","1",VLOOKUP(U13,Dicionários!$I$2:$J$22,2,0)),"1") -> 1 | X13: =IF(W$1="SIM",IF(W13="","1",VLOOKUP(W13,Dicionários!$K$2:$L$22,2,0)),"1") -> 1 | Y13: alto res | Z13: =IF(Y$1="SIM",IF(Y13="","1",VLOOKUP(Y13,Dicionários!$M$2:$N$12,2,0)),"1") -> 1.45 | AA13: 1 | AC13: 3º | AD13: =IF(AC$1="SIM",IF(AC13="","1",VLOOKUP(AC13,Dicionários!$O$2:$Q$22,$AD$2,0)),"1") -> 1.061 | AE13: 480000 | AF13: =IF(AE13="","",IF($AH$1="Terreno",AE13/G13,AE13/E13)) -> 4900.9598 | AG13: 0.9 | AH13: =IF(AE13="","",AF13*AG13) -> 4410.8638 | AJ13: =IF(E13="","",E13/$E$18) -> 1.0882222 | AK13: =ABS(E13-$E$18) -> 7.94 | AL13: =0.3*$E$18 -> 27 | AM13: =IF(AK13<=AL13,0.25,0.125) -> 0.25 | AO13: =IF(G13="","",G13/$G$18) | AP13: =ABS(G13-$G$18) -> 0 | AQ13: =0.3*$G$18 -> 0 | AR13: =IF(AP13<=AQ13,0.25,0.125) -> 0.25 | AT13: =IF(AND(G13>5000,K13>90),1,0) -> 0 | AU13: =IF(I13=0,1,IF(AT13=1,(4.8*(I13^2)*(G13^-0.4)),IF(K13<20,ROUND((K13/20)^0.5,3),IF(K13<33,1,IF(K13<90,ROUND((33/K13)^0.5,3),0.6))))) -> 1 | AW13: =IF(C13="",1,IF(C$1="SIM",$C$18/C13,1)) -> 1.1 | AX13: =IF(E13="",1,IF(E$1="SIM",AJ13^AM13,1)) -> 1.0213613 | AY13: =IF(G13="",1,IF(G$1="SIM",AO13^AR13,1)) -> 1 | AZ13: =IF(K13="",1,IF(K$1="SIM",$AU$18/AU13,1)) -> 1 | BA13: =IF(M$1="SIM",$N$18/N13,1) -> 1 | BB13: =$P$18/P13 -> 1 | BC13: =IF(Q$1="SIM",$R$18/R13,1) -> 1 | BD13: =IF(S$1="SIM",$T$18/T13,1) -> 1 | BE13: =IF(U$1="SIM",$V$18/V13,1) -> 1 | BF13: =IF(W$1="SIM",$X$18/X13,1) -> 1 | BG13: =IF(Y$1="SIM",$Z$18/Z13,1) -> 1 | BH13: =IF(AA13-$AA$18=0,1,1-0.067*(AA13-$AA$18)) -> 1.067 | BI13: =IF(AC$1="SIM",$AD$18/AD13,1) -> 0.98020735 | BJ13: =1/1+((AW13-1)+(AX13-1)+(AY13-1)+(AZ13-1))+(BA13-1)+(BB13-1)+(BC13-1)+(BD13-1)+(BE13-1)+(BF13-1)+(BG13-1)+(BH13-1)+(BI13-1) -> 1.1685687 | BL13: =IF(AH13="","",BJ13*AH13) -> 5154.3972 | BM13: =IF(BL13="","",IF(BR13="Sim",AH13*BJ13,"")) | BN13: =IF(BM13="","",ABS((BM13-$BM$18)/$BU$15)) | BO13: =IF(BM13="","",VLOOKUP($BU$16,Dicionários!$S$2:$T$31,2,0)) | BP13: =IF(BM13="","",IF(BN13>BO13,"REJEITADO","ACEITO")) | BR13: Não | BT13: Número de dados utilizados | BU13: {=SUMPRODUCT(--(BM3:BM17<>""),--(BR3:BR17="SIM"))} -> 14 | BW13: Médio estimado | BZ13: =$BZ$3*BZ6 -> 721063.32 | CE13: Intervalo de confiança de 80%
A14: 12 | B14: Rua F, 550 | C14: 1 | D14: =C14 -> 1 | E14: 91.44 | K14: =IF(G14="","",G14/I14) | N14: =IF(M$1="SIM",IF(M14="","1",VLOOKUP(M14,Dicionários!$A$2:$B$22,2,0)),"1") -> 1 | P14: =IF(O$1="SIM",IF(O14="","1",VLOOKUP(O14,Dicionários!$C$2:$D$22,2,0)),"1") -> 1 | R14: =IF(Q$1="SIM",IF(Q14="","1",VLOOKUP(Q14,Dicionários!$E$2:$F$22,2,0)),"1") -> 1 | T14: =IF(S$1="SIM",IF(S14="","1",VLOOKUP(S14,Dicionários!$G$2:$H$22,2,0)),"1") -> 1 | V14: =IF(U$1="SIM",IF(U14="","1",VLOOKUP(U14,Dicionários!$I$2:$J$22,2,0)),"1") -> 1 | X14: =IF(W$1="SIM",IF(W14="","1",VLOOKUP(W14,Dicionários!$K$2:$L$22,2,0)),"1") -> 1 | Y14: alto res | Z14: =IF(Y$1="SIM",IF(Y14="","1",VLOOKUP(Y14,Dicionários!$M$2:$N$12,2,0)),"1") -> 1.45 | AA14: 1 | AC14: 4º | AD14: =IF(AC$1="SIM",IF(AC14="","1",VLOOKUP(AC14,Dicionários!$O$2:$Q$22,$AD$2,0)),"1") -> 1.082 | AE14: 799000 | AF14: =IF(AE14="","",IF($AH$1="Terreno",AE14/G14,AE14/E14)) -> 8737.9703 | AG14: 0.9 | AH14: =IF(AE14="","",AF14*AG14) -> 7864.1732 | AJ14: =IF(E14="","",E14/$E$18) -> 1.016 | AK14: =ABS(E14-$E$18) -> 1.44 | AL14: =0.3*$E$18 -> 27 | AM14: =IF(AK14<=AL14,0.25,0.125) -> 0.25 | AO14: =IF(G14="","",G14/$G$18) | AP14: =ABS(G14-$G$18) -> 0 | AQ14: =0.3*$G$18 -> 0 | AR14: =IF(AP14<=AQ14,0.25,0.125) -> 0.25 | AT14: =IF(AND(G14>5000,K14>90),1,0) -> 0 | AU14: =IF(I14=0,1,IF(AT14=1,(4.8*(I14^2)*(G14^-0.4)),IF(K14<20,ROUND((K14/20)^0.5,3),IF(K14<33,1,IF(K14<90,ROUND((33/K14)^0.5,3),0.6))))) -> 1 | AW14: =IF(C14="",1,IF(C$1="SIM",$C$18/C14,1)) -> 1.1 | AX14: =IF(E14="",1,IF(E$1="SIM",AJ14^AM14,1)) -> 1.0039762 | AY14: =IF(G14="",1,IF(G$1="SIM",AO14^AR14,1)) -> 1 | AZ14: =IF(K14="",1,IF(K$1="SIM",$AU$18/AU14,1)) -> 1 | BA14: =IF(M$1="SIM",$N$18/N14,1) -> 1 | BB14: =$P$18/P14 -> 1 | BC14: =IF(Q$1="SIM",$R$18/R14,1) -> 1 | BD14: =IF(S$1="SIM",$T$18/T14,1) -> 1 | BE14: =IF(U$1="SIM",$V$18/V14,1) -> 1 | BF14: =IF(W$1="SIM",$X$18/X14,1) -> 1 | BG14: =IF(Y$1="SIM",$Z$18/Z14,1) -> 1 | BH14: =IF(AA14-$AA$18=0,1,1-0.067*(AA14-$AA$18)) -> 1.067 | BI14: =IF(AC$1="SIM",$AD$18/AD14,1) -> 0.96118299 | BJ14: =1/1+((AW14-1)+(AX14-1)+(AY14-1)+(AZ14-1))+(BA14-1)+(BB14-1)+(BC14-1)+(BD14-1)+(BE14-1)+(BF14-1)+(BG14-1)+(BH14-1)+(BI14-1) -> 1.1321592 | BL14: =IF(AH14="","",BJ14*AH14) -> 8903.4962 | BM14: =IF(BL14="","",IF(BR14="Sim",AH14*BJ14,"")) -> 8903.4962 | BN14: =IF(BM14="","",ABS((BM14-$BM$18)/$BU$15)) -> 1.2158189 | BO14: =IF(BM14="","",VLOOKUP($BU$16,Dicionários!$S$2:$T$31,2,0)) -> 2.06 | BP14: =IF(BM14="","",IF(BN14>BO14,"REJEITADO","ACEITO")) -> ACEITO | BR14: Sim | BT14: Média saneada | BU14: =AVERAGEIF($BR$3:$BR$17,"SIM",$BM$3:$BM$17) -> 8011.8146 | BW14: LI Campo de Arbítrio (-15%) | BZ14: =$BZ$3*BZ7 -> 612903.82 | CB14: =1-(BZ14/$BZ$13) -> 0.15 | CE14: * Ele mostra um intervalo de valores possíveis onde o verdadeiro valor médio provavelmente está.
A15: 13 | B15: Rua C, 161 | C15: 1.1 | D15: =C15 -> 1.1 | E15: 88.14 | K15: =IF(G15="","",G15/I15) | N15: =IF(M$1="SIM",IF(M15="","1",VLOOKUP(M15,Dicionários!$A$2:$B$22,2,0)),"1") -> 1 | P15: =IF(O$1="SIM",IF(O15="","1",VLOOKUP(O15,Dicionários!$C$2:$D$22,2,0)),"1") -> 1 | R15: =IF(Q$1="SIM",IF(Q15="","1",VLOOKUP(Q15,Dicionários!$E$2:$F$22,2,0)),"1") -> 1 | T15: =IF(S$1="SIM",IF(S15="","1",VLOOKUP(S15,Dicionários!$G$2:$H$22,2,0)),"1") -> 1 | V15: =IF(U$1="SIM",IF(U15="","1",VLOOKUP(U15,Dicionários!$I$2:$J$22,2,0)),"1") -> 1 | X15: =IF(W$1="SIM",IF(W15="","1",VLOOKUP(W15,Dicionários!$K$2:$L$22,2,0)),"1") -> 1 | Y15: normal res | Z15: =IF(Y$1="SIM",IF(Y15="","1",VLOOKUP(Y15,Dicionários!$M$2:$N$12,2,0)),"1") -> 1.3 | AA15: 1 | AC15: 5º | AD15: =IF(AC$1="SIM",IF(AC15="","1",VLOOKUP(AC15,Dicionários!$O$2:$Q$22,$AD$2,0)),"1") -> 1.104 | AE15: 771120 | AF15: =IF(AE15="","",IF($AH$1="Terreno",AE15/G15,AE15/E15)) -> 8748.8087 | AG15: 0.9 | AH15: =IF(AE15="","",AF15*AG15) -> 7873.9278 | AJ15: =IF(E15="","",E15/$E$18) -> 0.97933333 | AK15: =ABS(E15-$E$18) -> 1.86 | AL15: =0.3*$E$18 -> 27 | AM15: =IF(AK15<=AL15,0.25,0.125) -> 0.25 | AO15: =IF(G15="","",G15/$G$18) | AP15: =ABS(G15-$G$18) -> 0 | AQ15: =0.3*$G$18 -> 0 | AR15: =IF(AP15<=AQ15,0.25,0.125) -> 0.25 | AT15: =IF(AND(G15>5000,K15>90),1,0) -> 0 | AU15: =IF(I15=0,1,IF(AT15=1,(4.8*(I15^2)*(G15^-0.4)),IF(K15<20,ROUND((K15/20)^0.5,3),IF(K15<33,1,IF(K15<90,ROUND((33/K15)^0.5,3),0.6))))) -> 1 | AW15: =IF(C15="",1,IF(C$1="SIM",$C$18/C15,1)) -> 1 | AX15: =IF(E15="",1,IF(E$1="SIM",AJ15^AM15,1)) -> 0.9947928 | AY15: =IF(G15="",1,IF(G$1="SIM",AO15^AR15,1)) -> 1 | AZ15: =IF(K15="",1,IF(K$1="SIM",$AU$18/AU15,1)) -> 1 | BA15: =IF(M$1="SIM",$N$18/N15,1) -> 1 | BB15: =$P$18/P15 -> 1 | BC15: =IF(Q$1="SIM",$R$18/R15,1) -> 1 | BD15: =IF(S$1="SIM",$T$18/T15,1) -> 1 | BE15: =IF(U$1="SIM",$V$18/V15,1) -> 1 | BF15: =IF(W$1="SIM",$X$18/X15,1) -> 1 | BG15: =IF(Y$1="SIM",$Z$18/Z15,1) -> 1.1153846 | BH15: =IF(AA15-$AA$18=0,1,1-0.067*(AA15-$AA$18)) -> 1.067 | BI15: =IF(AC$1="SIM",$AD$18/AD15,1) -> 0.94202899 | BJ15: =1/1+((AW15-1)+(AX15-1)+(AY15-1)+(AZ15-1))+(BA15-1)+(BB15-1)+(BC15-1)+(BD15-1)+(BE15-1)+(BF15-1)+(BG15-1)+(BH15-1)+(BI15-1) -> 1.1192064 | BL15: =IF(AH15="","",BJ15*AH15) -> 8812.5505 | BM15: =IF(BL15="","",IF(BR15="Sim",AH15*BJ15,"")) -> 8812.5505 | BN15: =IF(BM15="","",ABS((BM15-$BM$18)/$BU$15)) -> 1.0918132 | BO15: =IF(BM15="","",VLOOKUP($BU$16,Dicionários!$S$2:$T$31,2,0)) -> 2.06 | BP15: =IF(BM15="","",IF(BN15>BO15,"REJEITADO","ACEITO")) -> ACEITO | BR15: Sim | BT15: Desvio padrão | BU15: {=_xlfn.STDEV.S(IF($BR$3:$BR$17="SIM",$BM$3:$BM$17))} -> 733.39998 | BW15: LS Campo de Arbítrio (+15%) | BZ15: =$BZ$3*BZ8 -> 829222.82 | CB15: =(BZ15/$BZ$13)-1 -> 0.15
A16: 14 | B16: Rua F, 550 | C16: 1 | D16: =C16 -> 1 | E16: 91.44 | K16: =IF(G16="","",G16/I16) | N16: =IF(M$1="SIM",IF(M16="","1",VLOOKUP(M16,Dicionários!$A$2:$B$22,2,0)),"1") -> 1 | P16: =IF(O$1="SIM",IF(O16="","1",VLOOKUP(O16,Dicionários!$C$2:$D$22,2,0)),"1") -> 1 | R16: =IF(Q$1="SIM",IF(Q16="","1",VLOOKUP(Q16,Dicionários!$E$2:$F$22,2,0)),"1") -> 1 | T16: =IF(S$1="SIM",IF(S16="","1",VLOOKUP(S16,Dicionários!$G$2:$H$22,2,0)),"1") -> 1 | V16: =IF(U$1="SIM",IF(U16="","1",VLOOKUP(U16,Dicionários!$I$2:$J$22,2,0)),"1") -> 1 | X16: =IF(W$1="SIM",IF(W16="","1",VLOOKUP(W16,Dicionários!$K$2:$L$22,2,0)),"1") -> 1 | Y16: alto res | Z16: =IF(Y$1="SIM",IF(Y16="","1",VLOOKUP(Y16,Dicionários!$M$2:$N$12,2,0)),"1") -> 1.45 | AA16: 1 | AC16: 5º | AD16: =IF(AC$1="SIM",IF(AC16="","1",VLOOKUP(AC16,Dicionários!$O$2:$Q$22,$AD$2,0)),"1") -> 1.104 | AE16: 848000 | AF16: =IF(AE16="","",IF($AH$1="Terreno",AE16/G16,AE16/E16)) -> 9273.8408 | AG16: 0.9 | AH16: =IF(AE16="","",AF16*AG16) -> 8346.4567 | AJ16: =IF(E16="","",E16/$E$18) -> 1.016 | AK16: =ABS(E16-$E$18) -> 1.44 | AL16: =0.3*$E$18 -> 27 | AM16: =IF(AK16<=AL16,0.25,0.125) -> 0.25 | AO16: =IF(G16="","",G16/$G$18) | AP16: =ABS(G16-$G$18) -> 0 | AQ16: =0.3*$G$18 -> 0 | AR16: =IF(AP16<=AQ16,0.25,0.125) -> 0.25 | AT16: =IF(AND(G16>5000,K16>90),1,0) -> 0 | AU16: =IF(I16=0,1,IF(AT16=1,(4.8*(I16^2)*(G16^-0.4)),IF(K16<20,ROUND((K16/20)^0.5,3),IF(K16<33,1,IF(K16<90,ROUND((33/K16)^0.5,3),0.6))))) -> 1 | AW16: =IF(C16="",1,IF(C$1="SIM",$C$18/C16,1)) -> 1.1 | AX16: =IF(E16="",1,IF(E$1="SIM",AJ16^AM16,1)) -> 1.0039762 | AY16: =IF(G16="",1,IF(G$1="SIM",AO16^AR16,1)) -> 1 | AZ16: =IF(K16="",1,IF(K$1="SIM",$AU$18/AU16,1)) -> 1 | BA16: =IF(M$1="SIM",$N$18/N16,1) -> 1 | BB16: =$P$18/P16 -> 1 | BC16: =IF(Q$1="SIM",$R$18/R16,1) -> 1 | BD16: =IF(S$1="SIM",$T$18/T16,1) -> 1 | BE16: =IF(U$1="SIM",$V$18/V16,1) -> 1 | BF16: =IF(W$1="SIM",$X$18/X16,1) -> 1 | BG16: =IF(Y$1="SIM",$Z$18/Z16,1) -> 1 | BH16: =IF(AA16-$AA$18=0,1,1-0.067*(AA16-$AA$18)) -> 1.067 | BI16: =IF(AC$1="SIM",$AD$18/AD16,1) -> 0.94202899 | BJ16: =1/1+((AW16-1)+(AX16-1)+(AY16-1)+(AZ16-1))+(BA16-1)+(BB16-1)+(BC16-1)+(BD16-1)+(BE16-1)+(BF16-1)+(BG16-1)+(BH16-1)+(BI16-1) -> 1.1130052 | BL16: =IF(AH16="","",BJ16*AH16) -> 9289.6498 | BM16: =IF(BL16="","",IF(BR16="Sim",AH16*BJ16,"")) -> 9289.6498 | BN16: =IF(BM16="","",ABS((BM16-$BM$18)/$BU$15)) -> 1.7423441 | BO16: =IF(BM16="","",VLOOKUP($BU$16,Dicionários!$S$2:$T$31,2,0)) -> 2.06 | BP16: =IF(BM16="","",IF(BN16>BO16,"REJEITADO","ACEITO")) -> ACEITO | BR16: Sim | BT16: Graus de liberdade (n-1) | BU16: =BU13-1 -> 13 | BW16: LI Intevalo de Confiança 80% | BZ16: =$BZ$3*BZ9 -> 696349.18 | CB16: =1-(BZ16/$BZ$13) -> 0.034274576
A17: 15 | B17: Rua F, 550 | C17: 1 | D17: =C17 -> 1 | E17: 91.44 | K17: =IF(G17="","",G17/I17) | N17: =IF(M$1="SIM",IF(M17="","1",VLOOKUP(M17,Dicionários!$A$2:$B$22,2,0)),"1") -> 1 | P17: =IF(O$1="SIM",IF(O17="","1",VLOOKUP(O17,Dicionários!$C$2:$D$22,2,0)),"1") -> 1 | R17: =IF(Q$1="SIM",IF(Q17="","1",VLOOKUP(Q17,Dicionários!$E$2:$F$22,2,0)),"1") -> 1 | T17: =IF(S$1="SIM",IF(S17="","1",VLOOKUP(S17,Dicionários!$G$2:$H$22,2,0)),"1") -> 1 | V17: =IF(U$1="SIM",IF(U17="","1",VLOOKUP(U17,Dicionários!$I$2:$J$22,2,0)),"1") -> 1 | X17: =IF(W$1="SIM",IF(W17="","1",VLOOKUP(W17,Dicionários!$K$2:$L$22,2,0)),"1") -> 1 | Y17: alto res | Z17: =IF(Y$1="SIM",IF(Y17="","1",VLOOKUP(Y17,Dicionários!$M$2:$N$12,2,0)),"1") -> 1.45 | AA17: 2 | AC17: 4º | AD17: =IF(AC$1="SIM",IF(AC17="","1",VLOOKUP(AC17,Dicionários!$O$2:$Q$22,$AD$2,0)),"1") -> 1.082 | AE17: 850000 | AF17: =IF(AE17="","",IF($AH$1="Terreno",AE17/G17,AE17/E17)) -> 9295.713 | AG17: 0.9 | AH17: =IF(AE17="","",AF17*AG17) -> 8366.1417 | AJ17: =IF(E17="","",E17/$E$18) -> 1.016 | AK17: =ABS(E17-$E$18) -> 1.44 | AL17: =0.3*$E$18 -> 27 | AM17: =IF(AK17<=AL17,0.25,0.125) -> 0.25 | AO17: =IF(G17="","",G17/$G$18) | AP17: =ABS(G17-$G$18) -> 0 | AQ17: =0.3*$G$18 -> 0 | AR17: =IF(AP17<=AQ17,0.25,0.125) -> 0.25 | AT17: =IF(AND(G17>5000,K17>90),1,0) -> 0 | AU17: =IF(I17=0,1,IF(AT17=1,(4.8*(I17^2)*(G17^-0.4)),IF(K17<20,ROUND((K17/20)^0.5,3),IF(K17<33,1,IF(K17<90,ROUND((33/K17)^0.5,3),0.6))))) -> 1 | AW17: =IF(C17="",1,IF(C$1="SIM",$C$18/C17,1)) -> 1.1 | AX17: =IF(E17="",1,IF(E$1="SIM",AJ17^AM17,1)) -> 1.0039762 | AY17: =IF(G17="",1,IF(G$1="SIM",AO17^AR17,1)) -> 1 | AZ17: =IF(K17="",1,IF(K$1="SIM",$AU$18/AU17,1)) -> 1 | BA17: =IF(M$1="SIM",$N$18/N17,1) -> 1 | BB17: =$P$18/P17 -> 1 | BC17: =IF(Q$1="SIM",$R$18/R17,1) -> 1 | BD17: =IF(S$1="SIM",$T$18/T17,1) -> 1 | BE17: =IF(U$1="SIM",$V$18/V17,1) -> 1 | BF17: =IF(W$1="SIM",$X$18/X17,1) -> 1 | BG17: =IF(Y$1="SIM",$Z$18/Z17,1) -> 1 | BH17: =IF(AA17-$AA$18=0,1,1-0.067*(AA17-$AA$18)) -> 1 | BI17: =IF(AC$1="SIM",$AD$18/AD17,1) -> 0.96118299 | BJ17: =1/1+((AW17-1)+(AX17-1)+(AY17-1)+(AZ17-1))+(BA17-1)+(BB17-1)+(BC17-1)+(BD17-1)+(BE17-1)+(BF17-1)+(BG17-1)+(BH17-1)+(BI17-1) -> 1.0651592 | BL17: =IF(AH17="","",BJ17*AH17) -> 8911.273 | BM17: =IF(BL17="","",IF(BR17="Sim",AH17*BJ17,"")) -> 8911.273 | BN17: =IF(BM17="","",ABS((BM17-$BM$18)/$BU$15)) -> 1.2264226 | BO17: =IF(BM17="","",VLOOKUP($BU$16,Dicionários!$S$2:$T$31,2,0)) -> 2.06 | BP17: =IF(BM17="","",IF(BN17>BO17,"REJEITADO","ACEITO")) -> ACEITO | BR17: Sim | BT17: Limite superior (1,15 * média) | BU17: =BU14*1.15 -> 9213.5868 | BW17: LS Intevalo de Confiança 80% | BZ17: =$BZ$3*BZ10 -> 745777.46 | CB17: =(BZ17/$BZ$13)-1 -> 0.034274576 | CE17: * No caso de um intervalo de confiança de 80% aplicado a um modelo, significa que, se o processo de amostragem e estimação fosse repetido muitas vezes, em 80 de cada 100 modelos estimados o intervalo conteria o valor verdadeiro do parâmetro.
A18: AVAL | C18: 1.1 | D18: =C18 -> 1.1 | E18: 90 | K18: =IF(G18="","",G18/I18) | N18: =IF(M$1="SIM",IF(M18="","1",VLOOKUP(M18,Dicionários!$A$2:$B$22,2,0)),"1") -> 1 | P18: =IF(O$1="SIM",IF(O18="","1",VLOOKUP(O18,Dicionários!$C$2:$D$22,2,0)),"1") -> 1 | R18: =IF(Q$1="SIM",IF(Q18="","1",VLOOKUP(Q18,Dicionários!$E$2:$F$22,2,0)),"1") -> 1 | T18: =IF(S$1="SIM",IF(S18="","1",VLOOKUP(S18,Dicionários!$G$2:$H$22,2,0)),"1") -> 1 | V18: =IF(U$1="SIM",IF(U18="","1",VLOOKUP(U18,Dicionários!$I$2:$J$22,2,0)),"1") -> 1 | X18: =IF(W$1="SIM",IF(W18="","1",VLOOKUP(W18,Dicionários!$K$2:$L$22,2,0)),"1") -> 1 | Y18: alto res | Z18: =IF(Y$1="SIM",IF(Y18="","1",VLOOKUP(Y18,Dicionários!$M$2:$N$12,2,0)),"1") -> 1.45 | AA18: 2 | AC18: 2º | AD18: =IF(AC$1="SIM",IF(AC18="","1",VLOOKUP(AC18,Dicionários!$O$2:$Q$22,$AD$2,0)),"1") -> 1.04 | AT18: =IF(AND(G18>5000,K18>90),1,0) -> 0 | AU18: =IF(I18=0,1,IF(AT18=1,(4.8*(I18^2)*(G18^-0.4)),IF(K18<20,ROUND((K18/20)^0.5,3),IF(K18<33,1,IF(K18<90,ROUND((33/K18)^0.5,3),0.6))))) -> 1 | BL18: =AVERAGE(BL3:BL17) -> 7821.3201 | BM18: =AVERAGE(BM3:BM17) -> 8011.8146 | BT18: Limite inferior (0,85 * média) | BU18: =BU14*0.85 -> 6810.0424
BT19: t-valor crítico (conf. 80%) | BU19: =VLOOKUP(BU16,Dicionários!V3:W39,2,0) -> 1.35
BT20: Limite infeiror IC | BU20: =BU14-BU19*(BU15/(BU13-1)^0.5) -> 7737.2131
BT21: Limite Supeiror IC | BU21: =BU14+BU19*(BU15/(BU13-1)^0.5) -> 8286.4162
BT22: Amplitude | BU22: =BU21-BU20 -> 549.2031
BT23: Amplitude percentual | BU23: =(BU22/BU14) -> 0.068549153

Sheet Ter_Carol
B1: Escolha as variáveis ---> | C1: SIM | E1: NÃO | G1: SIM | I1: SIM | K1: SIM | M1: SIM | O1: NÃO | Q1: NÃO | S1: NÃO | U1: NÃO | W1: NÃO | Y1: NÃO | AA1: NÃO | AC1: NÃO | AH1: Terreno | AJ1: FAC | AO1: FAT | AT1: FPE | AW1: =C1 -> SIM | AX1: =E1 -> NÃO | AY1: =G1 -> SIM | AZ1: =K1 -> SIM | BA1: =M1 -> SIM | BB1: =O1 -> NÃO | BC1: =Q1 -> NÃO | BD1: =S1 -> NÃO | BE1: =U1 -> NÃO | BF1: =W1 -> NÃO | BG1: =Y1 -> NÃO | BH1: =AA1 -> NÃO | BI1: =AC1 -> NÃO
A2: Nº | B2: ENDEREÇO | C2: Localização | E2: Área Construída | G2: Área Territorial | I2: Testada | K2: Prof. Equivalente | M2: Topografia | O2: Relevo | Q2: Superfície | S2: Aproveitamento | U2: Acessibilidade | W2: Id. Apa. Conserva. | Y2: Padrão Const. | AA2: Vaga | AC2: Andar Res | AD2: =IF(AC2="Andar Res",3,2) -> 3 | AE2: Valor | AF2: Valor Unitário | AG2: fon | AH2: Valor Unitário * fon | AJ2: raz | AK2: dif | AL2: x_ac | AM2: n | AO2: raz | AP2: dif | AQ2: x_at | AR2: n | AT2: h1 | AU2: COEF | AW2: fal | AX2: fac | AY2: fat | AZ2: fpe | BA2: ftp | BB2: frv | BC2: fsp | BD2: fap | BE2: fav | BF2: fic | BG2: fpd | BH2: fgv | BI2: fan | BJ2: fator final | BL2: Valor Unitário hom (todos) | BM2: Valor Unitário hom (s/ outliers) | BN2: z-score | BO2: vc | BP2: Status | BT2: Estatíticas iniciais com toda a amostra | BW2: Valores Calculados | CE2: Explicações
A3: 1 | B3: AV UM, 900 | C3: 1 | D3: =C3 -> 1 | G3: 456 | I3: 12 | K3: =IF(G3="","",G3/I3) -> 38 | N3: =IF(M$1="SIM",IF(M3="","1",VLOOKUP(M3,Dicionários!$A$2:$B$22,2,0)),"1") -> 1 | P3: =IF(O$1="SIM",IF(O3="","1",VLOOKUP(O3,Dicionários!$C$2:$D$22,2,0)),"1") -> 1 | R3: =IF(Q$1="SIM",IF(Q3="","1",VLOOKUP(Q3,Dicionários!$E$2:$F$22,2,0)),"1") -> 1 | T3: =IF(S$1="SIM",IF(S3="","1",VLOOKUP(S3,Dicionários!$G$2:$H$22,2,0)),"1") -> 1 | V3: =IF(U$1="SIM",IF(U3="","1",VLOOKUP(U3,Dicionários!$I$2:$J$22,2,0)),"1") -> 1 | X3: =IF(W$1="SIM",IF(W3="","1",VLOOKUP(W3,Dicionários!$K$2:$L$22,2,0)),"1") -> 1 | Z3: =IF(Y$1="SIM",IF(Y3="","1",VLOOKUP(Y3,Dicionários!$M$2:$N$12,2,0)),"1") -> 1 | AD3: =IF(AC$1="SIM",IF(AC3="","1",VLOOKUP(AC3,Dicionários!$O$2:$Q$22,$AD$2,0)),"1") -> 1 | AE3: 750000 | AF3: =IF(AE3="","",IF($AH$1="Terreno",AE3/G3,AE3/E3)) -> 1644.7368 | AG3: 1 | AH3: =IF(AE3="","",AF3*AG3) -> 1644.7368 | AJ3: =IF(E3="","",E3/$E$18) | AK3: =ABS(E3-$E$18) -> 0 | AL3: =0.3*$E$18 -> 0 | AM3: =IF(AK3<=AL3,0.25,0.125) -> 0.25 | AO3: =IF(G3="","",G3/$G$18) -> 0.912 | AP3: =ABS(G3-$G$18) -> 44 | AQ3: =0.3*$G$18 -> 150 | AR3: =IF(AP3<=AQ3,0.25,0.125) -> 0.25 | AT3: =IF(AND(G3>5000,K3>90),1,0) -> 0 | AU3: =IF(I3=0,1,IF(AT3=1,(4.8*(I3^2)*(G3^-0.4)),IF(K3<20,ROUND((K3/20)^0.5,3),IF(K3<33,1,IF(K3<90,ROUND((33/K3)^0.5,3),0.6))))) -> 0.932 | AW3: =IF(C3="",1,IF(C$1="SIM",$C$18/C3,1)) -> 1 | AX3: =IF(E3="",1,IF(E$1="SIM",AJ3^AM3,1)) -> 1 | AY3: =IF(G3="",1,IF(G$1="SIM",AO3^AR3,1)) -> 0.97723432 | AZ3: =IF(K3="",1,IF(K$1="SIM",$AU$18/AU3,1)) -> 0.87124464 | BA3: =IF(M$1="SIM",$N$18/N3,1) -> 1 | BB3: =IF(O$1="SIM",$P$18/P3,1) -> 1 | BC3: =IF(Q$1="SIM",$R$18/R3,1) -> 1 | BD3: =IF(S$1="SIM",$T$18/T3,1) -> 1 | BE3: =IF(U$1="SIM",$V$18/V3,1) -> 1 | BF3: =IF(W$1="SIM",$X$18/X3,1) -> 1 | BG3: =IF(Y$1="SIM",$Z$18/Z3,1) -> 1 | BH3: =IF(AA3-$AA$18=0,1,1-0.067*(AA3-$AA$18)) -> 1 | BI3: =IF(AC$1="SIM",$AD$18/AD3,1) -> 1 | BJ3: =1/1+((AW3-1)+(AX3-1)+(AY3-1)+(AZ3-1))+(BA3-1)+(BB3-1)+(BC3-1)+(BD3-1)+(BE3-1)+(BF3-1)+(BG3-1)+(BH3-1)+(BI3-1) -> 0.84847895 | BL3: =IF(AH3="","",BJ3*AH3) -> 1395.5246 | BM3: =IF(BL3="","",IF(BR3="Sim",AH3*BJ3,"")) -> 1395.5246 | BN3: =IF(BM3="","",ABS((BM3-$BM$18)/$BU$15)) -> 1.1187232 | BO3: =IF(BM3="","",VLOOKUP($BU$16,Dicionários!$S$2:$T$31,2,0)) -> 2.1 | BP3: =IF(BM3="","",IF(BN3>BO3,"REJEITADO","ACEITO")) -> ACEITO | BR3: Sim | BT3: Número de dados | BU3: =COUNTA(BL3:BL17) -> 15 | BW3: Área avaliando (m²): | BZ3: =IF($AH$1="Terreno",G18,E18) -> 500 | CB3: m² | CE3: Campo de Arbítrio
A4: 2 | B4: R DOIS, 107 | C4: 1 | D4: =C4 -> 1 | G4: 456 | I4: 12 | K4: =IF(G4="","",G4/I4) -> 38 | N4: =IF(M$1="SIM",IF(M4="","1",VLOOKUP(M4,Dicionários!$A$2:$B$22,2,0)),"1") -> 1 | P4: =IF(O$1="SIM",IF(O4="","1",VLOOKUP(O4,Dicionários!$C$2:$D$22,2,0)),"1") -> 1 | R4: =IF(Q$1="SIM",IF(Q4="","1",VLOOKUP(Q4,Dicionários!$E$2:$F$22,2,0)),"1") -> 1 | T4: =IF(S$1="SIM",IF(S4="","1",VLOOKUP(S4,Dicionários!$G$2:$H$22,2,0)),"1") -> 1 | V4: =IF(U$1="SIM",IF(U4="","1",VLOOKUP(U4,Dicionários!$I$2:$J$22,2,0)),"1") -> 1 | X4: =IF(W$1="SIM",IF(W4="","1",VLOOKUP(W4,Dicionários!$K$2:$L$22,2,0)),"1") -> 1 | Z4: =IF(Y$1="SIM",IF(Y4="","1",VLOOKUP(Y4,Dicionários!$M$2:$N$12,2,0)),"1") -> 1 | AD4: =IF(AC$1="SIM",IF(AC4="","1",VLOOKUP(AC4,Dicionários!$O$2:$Q$22,$AD$2,0)),"1") -> 1 | AE4: 540000 | AF4: =IF(AE4="","",IF($AH$1="Terreno",AE4/G4,AE4/E4)) -> 1184.2105 | AG4: 1 | AH4: =IF(AE4="","",AF4*AG4) -> 1184.2105 | AJ4: =IF(E4="","",E4/$E$18) | AK4: =ABS(E4-$E$18) -> 0 | AL4: =0.3*$E$18 -> 0 | AM4: =IF(AK4<=AL4,0.25,0.125) -> 0.25 | AO4: =IF(G4="","",G4/$G$18) -> 0.912 | AP4: =ABS(G4-$G$18) -> 44 | AQ4: =0.3*$G$18 -> 150 | AR4: =IF(AP4<=AQ4,0.25,0.125) -> 0.25 | AT4: =IF(AND(G4>5000,K4>90),1,0) -> 0 | AU4: =IF(I4=0,1,IF(AT4=1,(4.8*(I4^2)*(G4^-0.4)),IF(K4<20,ROUND((K4/20)^0.5,3),IF(K4<33,1,IF(K4<90,ROUND((33/K4)^0.5,3),0.6))))) -> 0.932 | AW4: =IF(C4="",1,IF(C$1="SIM",$C$18/C4,1)) -> 1 | AX4: =IF(E4="",1,IF(E$1="SIM",AJ4^AM4,1)) -> 1 | AY4: =IF(G4="",1,IF(G$1="SIM",AO4^AR4,1)) -> 0.97723432 | AZ4: =IF(K4="",1,IF(K$1="SIM",$AU$18/AU4,1)) -> 0.87124464 | BA4: =IF(M$1="SIM",$N$18/N4,1) -> 1 | BB4: =$P$18/P4 -> 1 | BC4: =IF(Q$1="SIM",$R$18/R4,1) -> 1 | BD4: =IF(S$1="SIM",$T$18/T4,1) -> 1 | BE4: =IF(U$1="SIM",$V$18/V4,1) -> 1 | BF4: =IF(W$1="SIM",$X$18/X4,1) -> 1 | BG4: =IF(Y$1="SIM",$Z$18/Z4,1) -> 1 | BH4: =IF(AA4-$AA$18=0,1,1-0.067*(AA4-$AA$18)) -> 1 | BI4: =IF(AC$1="SIM",$AD$18/AD4,1) -> 1 | BJ4: =1/1+((AW4-1)+(AX4-1)+(AY4-1)+(AZ4-1))+(BA4-1)+(BB4-1)+(BC4-1)+(BD4-1)+(BE4-1)+(BF4-1)+(BG4-1)+(BH4-1)+(BI4-1) -> 0.84847895 | BL4: =IF(AH4="","",BJ4*AH4) -> 1004.7777 | BM4: =IF(BL4="","",IF(BR4="Sim",AH4*BJ4,"")) -> 1004.7777 | BN4: =IF(BM4="","",ABS((BM4-$BM$18)/$BU$15)) -> 0.67901973 | BO4: =IF(BM4="","",VLOOKUP($BU$16,Dicionários!$S$2:$T$31,2,0)) -> 2.1 | BP4: =IF(BM4="","",IF(BN4>BO4,"REJEITADO","ACEITO")) -> ACEITO | BR4: Sim | BT4: Média | BU4: =BL18 -> 1152.3655 | BW4: ----------------------------------------------------------------------------------- | CE4: * É basicamente é uma margem de tolerância usada em avaliações. * Essa margem é de ±15% em torno do valor estimado. * Pode ser usado quando: *O modelo de cálculo não conseguiu considerar todas as variáveis importantes; *Faltam dados de mercado; *Não existem fatores de ajuste disponíveis; *Ou algumas variáveis não mostraram relevância estatística. * A ideia é que essa margem de ±15% ajuda a compensar possíveis influências que ficaram de fora, desde que o avaliador justifique o uso.
A5: 3 | B5: R DOIS, 110 | C5: 1 | D5: =C5 -> 1 | G5: 456 | I5: 12 | K5: =IF(G5="","",G5/I5) -> 38 | N5: =IF(M$1="SIM",IF(M5="","1",VLOOKUP(M5,Dicionários!$A$2:$B$22,2,0)),"1") -> 1 | P5: =IF(O$1="SIM",IF(O5="","1",VLOOKUP(O5,Dicionários!$C$2:$D$22,2,0)),"1") -> 1 | R5: =IF(Q$1="SIM",IF(Q5="","1",VLOOKUP(Q5,Dicionários!$E$2:$F$22,2,0)),"1") -> 1 | T5: =IF(S$1="SIM",IF(S5="","1",VLOOKUP(S5,Dicionários!$G$2:$H$22,2,0)),"1") -> 1 | V5: =IF(U$1="SIM",IF(U5="","1",VLOOKUP(U5,Dicionários!$I$2:$J$22,2,0)),"1") -> 1 | X5: =IF(W$1="SIM",IF(W5="","1",VLOOKUP(W5,Dicionários!$K$2:$L$22,2,0)),"1") -> 1 | Z5: =IF(Y$1="SIM",IF(Y5="","1",VLOOKUP(Y5,Dicionários!$M$2:$N$12,2,0)),"1") -> 1 | AD5: =IF(AC$1="SIM",IF(AC5="","1",VLOOKUP(AC5,Dicionários!$O$2:$Q$22,$AD$2,0)),"1") -> 1 | AE5: 850000 | AF5: =IF(AE5="","",IF($AH$1="Terreno",AE5/G5,AE5/E5)) -> 1864.0351 | AG5: 0.9 | AH5: =IF(AE5="","",AF5*AG5) -> 1677.6316 | AJ5: =IF(E5="","",E5/$E$18) | AK5: =ABS(E5-$E$18) -> 0 | AL5: =0.3*$E$18 -> 0 | AM5: =IF(AK5<=AL5,0.25,0.125) -> 0.25 | AO5: =IF(G5="","",G5/$G$18) -> 0.912 | AP5: =ABS(G5-$G$18) -> 44 | AQ5: =0.3*$G$18 -> 150 | AR5: =IF(AP5<=AQ5,0.25,0.125) -> 0.25 | AT5: =IF(AND(G5>5000,K5>90),1,0) -> 0 | AU5: =IF(I5=0,1,IF(AT5=1,(4.8*(I5^2)*(G5^-0.4)),IF(K5<20,ROUND((K5/20)^0.5,3),IF(K5<33,1,IF(K5<90,ROUND((33/K5)^0.5,3),0.6))))) -> 0.932 | AW5: =IF(C5="",1,IF(C$1="SIM",$C$18/C5,1)) -> 1 | AX5: =IF(E5="",1,IF(E$1="SIM",AJ5^AM5,1)) -> 1 | AY5: =IF(G5="",1,IF(G$1="SIM",AO5^AR5,1)) -> 0.97723432 | AZ5: =IF(K5="",1,IF(K$1="SIM",$AU$18/AU5,1)) -> 0.87124464 | BA5: =IF(M$1="SIM",$N$18/N5,1) -> 1 | BB5: =$P$18/P5 -> 1 | BC5: =IF(Q$1="SIM",$R$18/R5,1) -> 1 | BD5: =IF(S$1="SIM",$T$18/T5,1) -> 1 | BE5: =IF(U$1="SIM",$V$18/V5,1) -> 1 | BF5: =IF(W$1="SIM",$X$18/X5,1) -> 1 | BG5: =IF(Y$1="SIM",$Z$18/Z5,1) -> 1 | BH5: =IF(AA5-$AA$18=0,1,1-0.067*(AA5-$AA$18)) -> 1 | BI5: =IF(AC$1="SIM",$AD$18/AD5,1) -> 1 | BJ5: =1/1+((AW5-1)+(AX5-1)+(AY5-1)+(AZ5-1))+(BA5-1)+(BB5-1)+(BC5-1)+(BD5-1)+(BE5-1)+(BF5-1)+(BG5-1)+(BH5-1)+(BI5-1) -> 0.84847895 | BL5: =IF(AH5="","",BJ5*AH5) -> 1423.4351 | BM5: =IF(BL5="","",IF(BR5="Sim",AH5*BJ5,"")) -> 1423.4351 | BN5: =IF(BM5="","",ABS((BM5-$BM$18)/$BU$15)) -> 1.2471334 | BO5: =IF(BM5="","",VLOOKUP($BU$16,Dicionários!$S$2:$T$31,2,0)) -> 2.1 | BP5: =IF(BM5="","",IF(BN5>BO5,"REJEITADO","ACEITO")) -> ACEITO | BR5: Sim | BT5: Graus de liberdade (n-1) | BU5: =BU3-1 -> 14 | BW5: Valores Unitários (R$/m²)
A6: 4 | B6: R DOIS, 127 | C6: 1 | D6: =C6 -> 1 | G6: 422 | I6: 12 | K6: =IF(G6="","",G6/I6) -> 35.166667 | N6: =IF(M$1="SIM",IF(M6="","1",VLOOKUP(M6,Dicionários!$A$2:$B$22,2,0)),"1") -> 1 | P6: =IF(O$1="SIM",IF(O6="","1",VLOOKUP(O6,Dicionários!$C$2:$D$22,2,0)),"1") -> 1 | R6: =IF(Q$1="SIM",IF(Q6="","1",VLOOKUP(Q6,Dicionários!$E$2:$F$22,2,0)),"1") -> 1 | T6: =IF(S$1="SIM",IF(S6="","1",VLOOKUP(S6,Dicionários!$G$2:$H$22,2,0)),"1") -> 1 | V6: =IF(U$1="SIM",IF(U6="","1",VLOOKUP(U6,Dicionários!$I$2:$J$22,2,0)),"1") -> 1 | X6: =IF(W$1="SIM",IF(W6="","1",VLOOKUP(W6,Dicionários!$K$2:$L$22,2,0)),"1") -> 1 | Z6: =IF(Y$1="SIM",IF(Y6="","1",VLOOKUP(Y6,Dicionários!$M$2:$N$12,2,0)),"1") -> 1 | AD6: =IF(AC$1="SIM",IF(AC6="","1",VLOOKUP(AC6,Dicionários!$O$2:$Q$22,$AD$2,0)),"1") -> 1 | AE6: 530000 | AF6: =IF(AE6="","",IF($AH$1="Terreno",AE6/G6,AE6/E6)) -> 1255.9242 | AG6: 0.9 | AH6: =IF(AE6="","",AF6*AG6) -> 1130.3318 | AJ6: =IF(E6="","",E6/$E$18) | AK6: =ABS(E6-$E$18) -> 0 | AL6: =0.3*$E$18 -> 0 | AM6: =IF(AK6<=AL6,0.25,0.125) -> 0.25 | AO6: =IF(G6="","",G6/$G$18) -> 0.844 | AP6: =ABS(G6-$G$18) -> 78 | AQ6: =0.3*$G$18 -> 150 | AR6: =IF(AP6<=AQ6,0.25,0.125) -> 0.25 | AT6: =IF(AND(G6>5000,K6>90),1,0) -> 0 | AU6: =IF(I6=0,1,IF(AT6=1,(4.8*(I6^2)*(G6^-0.4)),IF(K6<20,ROUND((K6/20)^0.5,3),IF(K6<33,1,IF(K6<90,ROUND((33/K6)^0.5,3),0.6))))) -> 0.969 | AW6: =IF(C6="",1,IF(C$1="SIM",$C$18/C6,1)) -> 1 | AX6: =IF(E6="",1,IF(E$1="SIM",AJ6^AM6,1)) -> 1 | AY6: =IF(G6="",1,IF(G$1="SIM",AO6^AR6,1)) -> 0.95848564 | AZ6: =IF(K6="",1,IF(K$1="SIM",$AU$18/AU6,1)) -> 0.8379773 | BA6: =IF(M$1="SIM",$N$18/N6,1) -> 1 | BB6: =$P$18/P6 -> 1 | BC6: =IF(Q$1="SIM",$R$18/R6,1) -> 1 | BD6: =IF(S$1="SIM",$T$18/T6,1) -> 1 | BE6: =IF(U$1="SIM",$V$18/V6,1) -> 1 | BF6: =IF(W$1="SIM",$X$18/X6,1) -> 1 | BG6: =IF(Y$1="SIM",$Z$18/Z6,1) -> 1 | BH6: =IF(AA6-$AA$18=0,1,1-0.067*(AA6-$AA$18)) -> 1 | BI6: =IF(AC$1="SIM",$AD$18/AD6,1) -> 1 | BJ6: =1/1+((AW6-1)+(AX6-1)+(AY6-1)+(AZ6-1))+(BA6-1)+(BB6-1)+(BC6-1)+(BD6-1)+(BE6-1)+(BF6-1)+(BG6-1)+(BH6-1)+(BI6-1) -> 0.79646294 | BL6: =IF(AH6="","",BJ6*AH6) -> 900.26735 | BM6: =IF(BL6="","",IF(BR6="Sim",AH6*BJ6,"")) -> 900.26735 | BN6: =IF(BM6="","",ABS((BM6-$BM$18)/$BU$15)) -> 1.1598496 | BO6: =IF(BM6="","",VLOOKUP($BU$16,Dicionários!$S$2:$T$31,2,0)) -> 2.1 | BP6: =IF(BM6="","",IF(BN6>BO6,"REJEITADO","ACEITO")) -> ACEITO | BR6: Sim | BT6: Valor máximo | BU6: =LARGE($BL$3:$BL$17,1) -> 1576.6709 | BW6: Médio estimado | BZ6: =BU14 -> 1152.3655
A7: 5 | B7: R DOIS, 255 | C7: 1 | D7: =C7 -> 1 | G7: 705 | I7: 16 | K7: =IF(G7="","",G7/I7) -> 44.0625 | N7: =IF(M$1="SIM",IF(M7="","1",VLOOKUP(M7,Dicionários!$A$2:$B$22,2,0)),"1") -> 1 | P7: =IF(O$1="SIM",IF(O7="","1",VLOOKUP(O7,Dicionários!$C$2:$D$22,2,0)),"1") -> 1 | R7: =IF(Q$1="SIM",IF(Q7="","1",VLOOKUP(Q7,Dicionários!$E$2:$F$22,2,0)),"1") -> 1 | T7: =IF(S$1="SIM",IF(S7="","1",VLOOKUP(S7,Dicionários!$G$2:$H$22,2,0)),"1") -> 1 | V7: =IF(U$1="SIM",IF(U7="","1",VLOOKUP(U7,Dicionários!$I$2:$J$22,2,0)),"1") -> 1 | X7: =IF(W$1="SIM",IF(W7="","1",VLOOKUP(W7,Dicionários!$K$2:$L$22,2,0)),"1") -> 1 | Z7: =IF(Y$1="SIM",IF(Y7="","1",VLOOKUP(Y7,Dicionários!$M$2:$N$12,2,0)),"1") -> 1 | AD7: =IF(AC$1="SIM",IF(AC7="","1",VLOOKUP(AC7,Dicionários!$O$2:$Q$22,$AD$2,0)),"1") -> 1 | AE7: 745000 | AF7: =IF(AE7="","",IF($AH$1="Terreno",AE7/G7,AE7/E7)) -> 1056.7376 | AG7: 0.9 | AH7: =IF(AE7="","",AF7*AG7) -> 951.06383 | AJ7: =IF(E7="","",E7/$E$18) | AK7: =ABS(E7-$E$18) -> 0 | AL7: =0.3*$E$18 -> 0 | AM7: =IF(AK7<=AL7,0.25,0.125) -> 0.25 | AO7: =IF(G7="","",G7/$G$18) -> 1.41 | AP7: =ABS(G7-$G$18) -> 205 | AQ7: =0.3*$G$18 -> 150 | AR7: =IF(AP7<=AQ7,0.25,0.125) -> 0.125 | AT7: =IF(AND(G7>5000,K7>90),1,0) -> 0 | AU7: =IF(I7=0,1,IF(AT7=1,(4.8*(I7^2)*(G7^-0.4)),IF(K7<20,ROUND((K7/20)^0.5,3),IF(K7<33,1,IF(K7<90,ROUND((33/K7)^0.5,3),0.6))))) -> 0.865 | AW7: =IF(C7="",1,IF(C$1="SIM",$C$18/C7,1)) -> 1 | AX7: =IF(E7="",1,IF(E$1="SIM",AJ7^AM7,1)) -> 1 | AY7: =IF(G7="",1,IF(G$1="SIM",AO7^AR7,1)) -> 1.0438844 | AZ7: =IF(K7="",1,IF(K$1="SIM",$AU$18/AU7,1)) -> 0.93872832 | BA7: =IF(M$1="SIM",$N$18/N7,1) -> 1 | BB7: =$P$18/P7 -> 1 | BC7: =IF(Q$1="SIM",$R$18/R7,1) -> 1 | BD7: =IF(S$1="SIM",$T$18/T7,1) -> 1 | BE7: =IF(U$1="SIM",$V$18/V7,1) -> 1 | BF7: =IF(W$1="SIM",$X$18/X7,1) -> 1 | BG7: =IF(Y$1="SIM",$Z$18/Z7,1) -> 1 | BH7: =IF(AA7-$AA$18=0,1,1-0.067*(AA7-$AA$18)) -> 1 | BI7: =IF(AC$1="SIM",$AD$18/AD7,1) -> 1 | BJ7: =1/1+((AW7-1)+(AX7-1)+(AY7-1)+(AZ7-1))+(BA7-1)+(BB7-1)+(BC7-1)+(BD7-1)+(BE7-1)+(BF7-1)+(BG7-1)+(BH7-1)+(BI7-1) -> 0.98261268 | BL7: =IF(AH7="","",BJ7*AH7) -> 934.52738 | BM7: =IF(BL7="","",IF(BR7="Sim",AH7*BJ7,"")) -> 934.52738 | BN7: =IF(BM7="","",ABS((BM7-$BM$18)/$BU$15)) -> 1.0022265 | BO7: =IF(BM7="","",VLOOKUP($BU$16,Dicionários!$S$2:$T$31,2,0)) -> 2.1 | BP7: =IF(BM7="","",IF(BN7>BO7,"REJEITADO","ACEITO")) -> ACEITO | BR7: Sim | BT7: Valor mínimo | BU7: =SMALL($BL$3:$BL$17,1) -> 900.26735 | BW7: LI Campo de Arbítrio (-15%) | BZ7: =BU18 -> 979.51064
A8: 6 | B8: R TRÊS, 80 | C8: 1 | D8: =C8 -> 1 | G8: 432 | I8: 18 | K8: =IF(G8="","",G8/I8) -> 24 | N8: =IF(M$1="SIM",IF(M8="","1",VLOOKUP(M8,Dicionários!$A$2:$B$22,2,0)),"1") -> 1 | P8: =IF(O$1="SIM",IF(O8="","1",VLOOKUP(O8,Dicionários!$C$2:$D$22,2,0)),"1") -> 1 | R8: =IF(Q$1="SIM",IF(Q8="","1",VLOOKUP(Q8,Dicionários!$E$2:$F$22,2,0)),"1") -> 1 | T8: =IF(S$1="SIM",IF(S8="","1",VLOOKUP(S8,Dicionários!$G$2:$H$22,2,0)),"1") -> 1 | V8: =IF(U$1="SIM",IF(U8="","1",VLOOKUP(U8,Dicionários!$I$2:$J$22,2,0)),"1") -> 1 | X8: =IF(W$1="SIM",IF(W8="","1",VLOOKUP(W8,Dicionários!$K$2:$L$22,2,0)),"1") -> 1 | Z8: =IF(Y$1="SIM",IF(Y8="","1",VLOOKUP(Y8,Dicionários!$M$2:$N$12,2,0)),"1") -> 1 | AD8: =IF(AC$1="SIM",IF(AC8="","1",VLOOKUP(AC8,Dicionários!$O$2:$Q$22,$AD$2,0)),"1") -> 1 | AE8: 630000 | AF8: =IF(AE8="","",IF($AH$1="Terreno",AE8/G8,AE8/E8)) -> 1458.3333 | AG8: 0.9 | AH8: =IF(AE8="","",AF8*AG8) -> 1312.5 | AJ8: =IF(E8="","",E8/$E$18) | AK8: =ABS(E8-$E$18) -> 0 | AL8: =0.3*$E$18 -> 0 | AM8: =IF(AK8<=AL8,0.25,0.125) -> 0.25 | AO8: =IF(G8="","",G8/$G$18) -> 0.864 | AP8: =ABS(G8-$G$18) -> 68 | AQ8: =0.3*$G$18 -> 150 | AR8: =IF(AP8<=AQ8,0.25,0.125) -> 0.25 | AT8: =IF(AND(G8>5000,K8>90),1,0) -> 0 | AU8: =IF(I8=0,1,IF(AT8=1,(4.8*(I8^2)*(G8^-0.4)),IF(K8<20,ROUND((K8/20)^0.5,3),IF(K8<33,1,IF(K8<90,ROUND((33/K8)^0.5,3),0.6))))) -> 1 | AW8: =IF(C8="",1,IF(C$1="SIM",$C$18/C8,1)) -> 1 | AX8: =IF(E8="",1,IF(E$1="SIM",AJ8^AM8,1)) -> 1 | AY8: =IF(G8="",1,IF(G$1="SIM",AO8^AR8,1)) -> 0.9641141 | AZ8: =IF(K8="",1,IF(K$1="SIM",$AU$18/AU8,1)) -> 0.812 | BA8: =IF(M$1="SIM",$N$18/N8,1) -> 1 | BB8: =$P$18/P8 -> 1 | BC8: =IF(Q$1="SIM",$R$18/R8,1) -> 1 | BD8: =IF(S$1="SIM",$T$18/T8,1) -> 1 | BE8: =IF(U$1="SIM",$V$18/V8,1) -> 1 | BF8: =IF(W$1="SIM",$X$18/X8,1) -> 1 | BG8: =IF(Y$1="SIM",$Z$18/Z8,1) -> 1 | BH8: =IF(AA8-$AA$18=0,1,1-0.067*(AA8-$AA$18)) -> 1 | BI8: =IF(AC$1="SIM",$AD$18/AD8,1) -> 1 | BJ8: =1/1+((AW8-1)+(AX8-1)+(AY8-1)+(AZ8-1))+(BA8-1)+(BB8-1)+(BC8-1)+(BD8-1)+(BE8-1)+(BF8-1)+(BG8-1)+(BH8-1)+(BI8-1) -> 0.7761141 | BL8: =IF(AH8="","",BJ8*AH8) -> 1018.6498 | BM8: =IF(BL8="","",IF(BR8="Sim",AH8*BJ8,"")) -> 1018.6498 | BN8: =IF(BM8="","",ABS((BM8-$BM$18)/$BU$15)) -> 0.61519738 | BO8: =IF(BM8="","",VLOOKUP($BU$16,Dicionários!$S$2:$T$31,2,0)) -> 2.1 | BP8: =IF(BM8="","",IF(BN8>BO8,"REJEITADO","ACEITO")) -> ACEITO | BR8: Sim | BT8: Limite superior (1,15 * média) | BU8: =1.15*$BU$4 -> 1325.2203 | BW8: LS Campo de Arbítrio (+15%) | BZ8: =BU17 -> 1325.2203
